[2019-04-30 02:35:19,210][Thread-4:140510728455936][task_id:django.request][exception.py:135][ERROR][Internal Server Error: /stockinfo/]
Traceback (most recent call last):
  File "/usr/local/lib/python3.5/dist-packages/django/core/handlers/exception.py", line 41, in inner
    response = get_response(request)
  File "/usr/local/lib/python3.5/dist-packages/django/core/handlers/base.py", line 187, in _get_response
    response = self.process_exception_by_middleware(e, request)
  File "/usr/local/lib/python3.5/dist-packages/django/core/handlers/base.py", line 185, in _get_response
    response = wrapped_callback(request, *callback_args, **callback_kwargs)
  File "/home/tarena/PycharmProjects/StockProject/index/views.py", line 29, in stockinfo
    dict.append(dict2)
AttributeError: 'dict' object has no attribute 'append'
[2019-04-30 02:35:19,382][Thread-4:140510728455936][task_id:django.server][basehttp.py:124][ERROR]["GET /stockinfo/ HTTP/1.1" 500 18482]
[2019-04-30 02:39:30,831][Thread-4:140424005207808][task_id:django.request][exception.py:135][ERROR][Internal Server Error: /stockinfo/]
Traceback (most recent call last):
  File "/usr/local/lib/python3.5/dist-packages/django/core/handlers/exception.py", line 41, in inner
    response = get_response(request)
  File "/usr/local/lib/python3.5/dist-packages/django/core/handlers/base.py", line 187, in _get_response
    response = self.process_exception_by_middleware(e, request)
  File "/usr/local/lib/python3.5/dist-packages/django/core/handlers/base.py", line 185, in _get_response
    response = wrapped_callback(request, *callback_args, **callback_kwargs)
  File "/home/tarena/PycharmProjects/StockProject/index/views.py", line 27, in stockinfo
    ft = dt.strptime(str,'%Y-%m-%d')
  File "/usr/lib/python3.5/_strptime.py", line 510, in _strptime_datetime
    tt, fraction = _strptime(data_string, format)
  File "/usr/lib/python3.5/_strptime.py", line 343, in _strptime
    (data_string, format))
ValueError: time data '19931018' does not match format '%Y-%m-%d'
[2019-04-30 02:39:31,064][Thread-4:140424005207808][task_id:django.server][basehttp.py:124][ERROR]["GET /stockinfo/ HTTP/1.1" 500 18735]
[2019-04-30 02:44:24,044][Thread-4:140283281344256][task_id:django.request][exception.py:135][ERROR][Internal Server Error: /stockinfo/]
Traceback (most recent call last):
  File "/usr/local/lib/python3.5/dist-packages/django/core/handlers/exception.py", line 41, in inner
    response = get_response(request)
  File "/usr/local/lib/python3.5/dist-packages/django/core/handlers/base.py", line 187, in _get_response
    response = self.process_exception_by_middleware(e, request)
  File "/usr/local/lib/python3.5/dist-packages/django/core/handlers/base.py", line 185, in _get_response
    response = wrapped_callback(request, *callback_args, **callback_kwargs)
  File "/home/tarena/PycharmProjects/StockProject/index/views.py", line 28, in stockinfo
    newlist = np.insert(stlist,[4,6])
TypeError: insert() missing 1 required positional argument: 'values'
[2019-04-30 02:44:24,130][Thread-4:140283281344256][task_id:django.server][basehttp.py:124][ERROR]["GET /stockinfo/ HTTP/1.1" 500 18515]
[2019-04-30 03:24:52,122][Thread-4:140455092877056][task_id:django.request][exception.py:135][ERROR][Internal Server Error: /stockinfo/]
Traceback (most recent call last):
  File "/usr/local/lib/python3.5/dist-packages/pandas/core/indexes/base.py", line 2657, in get_loc
    return self._engine.get_loc(key)
  File "pandas/_libs/index.pyx", line 108, in pandas._libs.index.IndexEngine.get_loc
  File "pandas/_libs/index.pyx", line 132, in pandas._libs.index.IndexEngine.get_loc
  File "pandas/_libs/hashtable_class_helper.pxi", line 1601, in pandas._libs.hashtable.PyObjectHashTable.get_item
  File "pandas/_libs/hashtable_class_helper.pxi", line 1608, in pandas._libs.hashtable.PyObjectHashTable.get_item
KeyError: 'code'

During handling of the above exception, another exception occurred:

Traceback (most recent call last):
  File "/usr/local/lib/python3.5/dist-packages/django/core/handlers/exception.py", line 41, in inner
    response = get_response(request)
  File "/usr/local/lib/python3.5/dist-packages/django/core/handlers/base.py", line 187, in _get_response
    response = self.process_exception_by_middleware(e, request)
  File "/usr/local/lib/python3.5/dist-packages/django/core/handlers/base.py", line 185, in _get_response
    response = wrapped_callback(request, *callback_args, **callback_kwargs)
  File "/home/tarena/PycharmProjects/StockProject/index/views.py", line 27, in stockinfo
    print("code:",stocklist['code'][i])
  File "/usr/local/lib/python3.5/dist-packages/pandas/core/frame.py", line 2927, in __getitem__
    indexer = self.columns.get_loc(key)
  File "/usr/local/lib/python3.5/dist-packages/pandas/core/indexes/base.py", line 2659, in get_loc
    return self._engine.get_loc(self._maybe_cast_indexer(key))
  File "pandas/_libs/index.pyx", line 108, in pandas._libs.index.IndexEngine.get_loc
  File "pandas/_libs/index.pyx", line 132, in pandas._libs.index.IndexEngine.get_loc
  File "pandas/_libs/hashtable_class_helper.pxi", line 1601, in pandas._libs.hashtable.PyObjectHashTable.get_item
  File "pandas/_libs/hashtable_class_helper.pxi", line 1608, in pandas._libs.hashtable.PyObjectHashTable.get_item
KeyError: 'code'
[2019-04-30 03:24:52,332][Thread-4:140455092877056][task_id:django.server][basehttp.py:124][ERROR]["GET /stockinfo/ HTTP/1.1" 500 18967]
[2019-04-30 03:25:37,585][Thread-4:139760046372608][task_id:django.request][exception.py:135][ERROR][Internal Server Error: /stockinfo/]
Traceback (most recent call last):
  File "/usr/local/lib/python3.5/dist-packages/pandas/core/indexes/base.py", line 2657, in get_loc
    return self._engine.get_loc(key)
  File "pandas/_libs/index.pyx", line 108, in pandas._libs.index.IndexEngine.get_loc
  File "pandas/_libs/index.pyx", line 132, in pandas._libs.index.IndexEngine.get_loc
  File "pandas/_libs/hashtable_class_helper.pxi", line 1601, in pandas._libs.hashtable.PyObjectHashTable.get_item
  File "pandas/_libs/hashtable_class_helper.pxi", line 1608, in pandas._libs.hashtable.PyObjectHashTable.get_item
KeyError: 'code'

During handling of the above exception, another exception occurred:

Traceback (most recent call last):
  File "/usr/local/lib/python3.5/dist-packages/django/core/handlers/exception.py", line 41, in inner
    response = get_response(request)
  File "/usr/local/lib/python3.5/dist-packages/django/core/handlers/base.py", line 187, in _get_response
    response = self.process_exception_by_middleware(e, request)
  File "/usr/local/lib/python3.5/dist-packages/django/core/handlers/base.py", line 185, in _get_response
    response = wrapped_callback(request, *callback_args, **callback_kwargs)
  File "/home/tarena/PycharmProjects/StockProject/index/views.py", line 26, in stockinfo
    print("code:",stocklist['code'])
  File "/usr/local/lib/python3.5/dist-packages/pandas/core/frame.py", line 2927, in __getitem__
    indexer = self.columns.get_loc(key)
  File "/usr/local/lib/python3.5/dist-packages/pandas/core/indexes/base.py", line 2659, in get_loc
    return self._engine.get_loc(self._maybe_cast_indexer(key))
  File "pandas/_libs/index.pyx", line 108, in pandas._libs.index.IndexEngine.get_loc
  File "pandas/_libs/index.pyx", line 132, in pandas._libs.index.IndexEngine.get_loc
  File "pandas/_libs/hashtable_class_helper.pxi", line 1601, in pandas._libs.hashtable.PyObjectHashTable.get_item
  File "pandas/_libs/hashtable_class_helper.pxi", line 1608, in pandas._libs.hashtable.PyObjectHashTable.get_item
KeyError: 'code'
[2019-04-30 03:25:37,733][Thread-4:139760046372608][task_id:django.server][basehttp.py:124][ERROR]["GET /stockinfo/ HTTP/1.1" 500 18961]
[2019-04-30 03:32:36,224][Thread-4:140243559798528][task_id:django.request][exception.py:135][ERROR][Internal Server Error: /stockinfo/]
Traceback (most recent call last):
  File "/usr/local/lib/python3.5/dist-packages/django/core/handlers/exception.py", line 41, in inner
    response = get_response(request)
  File "/usr/local/lib/python3.5/dist-packages/django/core/handlers/base.py", line 187, in _get_response
    response = self.process_exception_by_middleware(e, request)
  File "/usr/local/lib/python3.5/dist-packages/django/core/handlers/base.py", line 185, in _get_response
    response = wrapped_callback(request, *callback_args, **callback_kwargs)
  File "/home/tarena/PycharmProjects/StockProject/index/views.py", line 40, in stockinfo
    stlist = list(string)
TypeError: 'numpy.int64' object is not iterable
[2019-04-30 03:32:36,334][Thread-4:140243559798528][task_id:django.server][basehttp.py:124][ERROR]["GET /stockinfo/ HTTP/1.1" 500 18477]
[2019-04-30 03:33:55,547][Thread-4:140221219862272][task_id:django.request][exception.py:135][ERROR][Internal Server Error: /stockinfo/]
Traceback (most recent call last):
  File "/usr/local/lib/python3.5/dist-packages/django/core/handlers/exception.py", line 41, in inner
    response = get_response(request)
  File "/usr/local/lib/python3.5/dist-packages/django/core/handlers/base.py", line 187, in _get_response
    response = self.process_exception_by_middleware(e, request)
  File "/usr/local/lib/python3.5/dist-packages/django/core/handlers/base.py", line 185, in _get_response
    response = wrapped_callback(request, *callback_args, **callback_kwargs)
  File "/home/tarena/PycharmProjects/StockProject/index/views.py", line 40, in stockinfo
    newlist = np.insert(stlist, [4, 6], ['-', '-'])
  File "/usr/local/lib/python3.5/dist-packages/numpy/lib/function_base.py", line 4623, in insert
    old_mask[indices] = False
IndexError: index 4 is out of bounds for axis 0 with size 3
[2019-04-30 03:33:55,743][Thread-4:140221219862272][task_id:django.server][basehttp.py:124][ERROR]["GET /stockinfo/ HTTP/1.1" 500 18649]
[2019-04-30 06:17:58,053][Thread-2:140557996504832][task_id:django.request][exception.py:135][ERROR][Internal Server Error: /]
Traceback (most recent call last):
  File "/usr/local/lib/python3.5/dist-packages/django/template/base.py", line 507, in parse
    compile_func = self.tags[command]
KeyError: 'static'

During handling of the above exception, another exception occurred:

Traceback (most recent call last):
  File "/usr/local/lib/python3.5/dist-packages/django/core/handlers/exception.py", line 41, in inner
    response = get_response(request)
  File "/usr/local/lib/python3.5/dist-packages/django/core/handlers/base.py", line 187, in _get_response
    response = self.process_exception_by_middleware(e, request)
  File "/usr/local/lib/python3.5/dist-packages/django/core/handlers/base.py", line 185, in _get_response
    response = wrapped_callback(request, *callback_args, **callback_kwargs)
  File "/home/tarena/PycharmProjects/StockProject/index/views.py", line 17, in index
    return render(req,'index.html')
  File "/usr/local/lib/python3.5/dist-packages/django/shortcuts.py", line 30, in render
    content = loader.render_to_string(template_name, context, request, using=using)
  File "/usr/local/lib/python3.5/dist-packages/django/template/loader.py", line 68, in render_to_string
    return template.render(context, request)
  File "/usr/local/lib/python3.5/dist-packages/django/template/backends/django.py", line 66, in render
    return self.template.render(context)
  File "/usr/local/lib/python3.5/dist-packages/django/template/base.py", line 207, in render
    return self._render(context)
  File "/usr/local/lib/python3.5/dist-packages/django/template/base.py", line 199, in _render
    return self.nodelist.render(context)
  File "/usr/local/lib/python3.5/dist-packages/django/template/base.py", line 990, in render
    bit = node.render_annotated(context)
  File "/usr/local/lib/python3.5/dist-packages/django/template/base.py", line 957, in render_annotated
    return self.render(context)
  File "/usr/local/lib/python3.5/dist-packages/django/template/loader_tags.py", line 154, in render
    compiled_parent = self.get_parent(context)
  File "/usr/local/lib/python3.5/dist-packages/django/template/loader_tags.py", line 151, in get_parent
    return self.find_template(parent, context)
  File "/usr/local/lib/python3.5/dist-packages/django/template/loader_tags.py", line 131, in find_template
    template_name, skip=history,
  File "/usr/local/lib/python3.5/dist-packages/django/template/engine.py", line 136, in find_template
    name, template_dirs=dirs, skip=skip,
  File "/usr/local/lib/python3.5/dist-packages/django/template/loaders/base.py", line 44, in get_template
    contents, origin, origin.template_name, self.engine,
  File "/usr/local/lib/python3.5/dist-packages/django/template/base.py", line 191, in __init__
    self.nodelist = self.compile_nodelist()
  File "/usr/local/lib/python3.5/dist-packages/django/template/base.py", line 230, in compile_nodelist
    return parser.parse()
  File "/usr/local/lib/python3.5/dist-packages/django/template/base.py", line 509, in parse
    self.invalid_block_tag(token, command, parse_until)
  File "/usr/local/lib/python3.5/dist-packages/django/template/base.py", line 571, in invalid_block_tag
    "or load this tag?" % (token.lineno, command)
django.template.exceptions.TemplateSyntaxError: Invalid block tag on line 6: 'static'. Did you forget to register or load this tag?
[2019-04-30 06:17:59,944][Thread-2:140557996504832][task_id:django.server][basehttp.py:124][ERROR]["GET / HTTP/1.1" 500 167326]
[2019-04-30 06:22:10,281][Thread-4:140557987849984][task_id:django.request][exception.py:135][ERROR][Internal Server Error: /]
Traceback (most recent call last):
  File "/usr/local/lib/python3.5/dist-packages/django/core/handlers/exception.py", line 41, in inner
    response = get_response(request)
  File "/usr/local/lib/python3.5/dist-packages/django/core/handlers/base.py", line 187, in _get_response
    response = self.process_exception_by_middleware(e, request)
  File "/usr/local/lib/python3.5/dist-packages/django/core/handlers/base.py", line 185, in _get_response
    response = wrapped_callback(request, *callback_args, **callback_kwargs)
  File "/home/tarena/PycharmProjects/StockProject/index/views.py", line 17, in index
    return render(req,'index.html')
  File "/usr/local/lib/python3.5/dist-packages/django/shortcuts.py", line 30, in render
    content = loader.render_to_string(template_name, context, request, using=using)
  File "/usr/local/lib/python3.5/dist-packages/django/template/loader.py", line 68, in render_to_string
    return template.render(context, request)
  File "/usr/local/lib/python3.5/dist-packages/django/template/backends/django.py", line 66, in render
    return self.template.render(context)
  File "/usr/local/lib/python3.5/dist-packages/django/template/base.py", line 207, in render
    return self._render(context)
  File "/usr/local/lib/python3.5/dist-packages/django/template/base.py", line 199, in _render
    return self.nodelist.render(context)
  File "/usr/local/lib/python3.5/dist-packages/django/template/base.py", line 990, in render
    bit = node.render_annotated(context)
  File "/usr/local/lib/python3.5/dist-packages/django/template/base.py", line 957, in render_annotated
    return self.render(context)
  File "/usr/local/lib/python3.5/dist-packages/django/template/loader_tags.py", line 177, in render
    return compiled_parent._render(context)
  File "/usr/local/lib/python3.5/dist-packages/django/template/base.py", line 199, in _render
    return self.nodelist.render(context)
  File "/usr/local/lib/python3.5/dist-packages/django/template/base.py", line 990, in render
    bit = node.render_annotated(context)
  File "/usr/local/lib/python3.5/dist-packages/django/template/base.py", line 957, in render_annotated
    return self.render(context)
  File "/usr/local/lib/python3.5/dist-packages/django/template/defaulttags.py", line 458, in render
    url = reverse(view_name, args=args, kwargs=kwargs, current_app=current_app)
  File "/usr/local/lib/python3.5/dist-packages/django/urls/base.py", line 91, in reverse
    return force_text(iri_to_uri(resolver._reverse_with_prefix(view, prefix, *args, **kwargs)))
  File "/usr/local/lib/python3.5/dist-packages/django/urls/resolvers.py", line 497, in _reverse_with_prefix
    raise NoReverseMatch(msg)
django.urls.exceptions.NoReverseMatch: Reverse for 'login' not found. 'login' is not a valid view function or pattern name.
[2019-04-30 06:22:10,494][Thread-4:140557987849984][task_id:django.server][basehttp.py:124][ERROR]["GET / HTTP/1.1" 500 148078]
[2019-04-30 06:24:19,623][Thread-2:139703350642432][task_id:django.request][exception.py:135][ERROR][Internal Server Error: /]
Traceback (most recent call last):
  File "/usr/local/lib/python3.5/dist-packages/django/core/handlers/exception.py", line 41, in inner
    response = get_response(request)
  File "/usr/local/lib/python3.5/dist-packages/django/core/handlers/base.py", line 187, in _get_response
    response = self.process_exception_by_middleware(e, request)
  File "/usr/local/lib/python3.5/dist-packages/django/core/handlers/base.py", line 185, in _get_response
    response = wrapped_callback(request, *callback_args, **callback_kwargs)
  File "/home/tarena/PycharmProjects/StockProject/index/views.py", line 17, in index
    return render(req,'index.html')
  File "/usr/local/lib/python3.5/dist-packages/django/shortcuts.py", line 30, in render
    content = loader.render_to_string(template_name, context, request, using=using)
  File "/usr/local/lib/python3.5/dist-packages/django/template/loader.py", line 68, in render_to_string
    return template.render(context, request)
  File "/usr/local/lib/python3.5/dist-packages/django/template/backends/django.py", line 66, in render
    return self.template.render(context)
  File "/usr/local/lib/python3.5/dist-packages/django/template/base.py", line 207, in render
    return self._render(context)
  File "/usr/local/lib/python3.5/dist-packages/django/template/base.py", line 199, in _render
    return self.nodelist.render(context)
  File "/usr/local/lib/python3.5/dist-packages/django/template/base.py", line 990, in render
    bit = node.render_annotated(context)
  File "/usr/local/lib/python3.5/dist-packages/django/template/base.py", line 957, in render_annotated
    return self.render(context)
  File "/usr/local/lib/python3.5/dist-packages/django/template/loader_tags.py", line 177, in render
    return compiled_parent._render(context)
  File "/usr/local/lib/python3.5/dist-packages/django/template/base.py", line 199, in _render
    return self.nodelist.render(context)
  File "/usr/local/lib/python3.5/dist-packages/django/template/base.py", line 990, in render
    bit = node.render_annotated(context)
  File "/usr/local/lib/python3.5/dist-packages/django/template/base.py", line 957, in render_annotated
    return self.render(context)
  File "/usr/local/lib/python3.5/dist-packages/django/template/defaulttags.py", line 458, in render
    url = reverse(view_name, args=args, kwargs=kwargs, current_app=current_app)
  File "/usr/local/lib/python3.5/dist-packages/django/urls/base.py", line 91, in reverse
    return force_text(iri_to_uri(resolver._reverse_with_prefix(view, prefix, *args, **kwargs)))
  File "/usr/local/lib/python3.5/dist-packages/django/urls/resolvers.py", line 497, in _reverse_with_prefix
    raise NoReverseMatch(msg)
django.urls.exceptions.NoReverseMatch: Reverse for 'userinfo/login' not found. 'userinfo/login' is not a valid view function or pattern name.
[2019-04-30 06:24:19,813][Thread-2:139703350642432][task_id:django.server][basehttp.py:124][ERROR]["GET / HTTP/1.1" 500 148294]
[2019-04-30 06:25:15,800][Thread-6:140253604398848][task_id:django.request][exception.py:135][ERROR][Internal Server Error: /]
Traceback (most recent call last):
  File "/usr/local/lib/python3.5/dist-packages/django/core/handlers/exception.py", line 41, in inner
    response = get_response(request)
  File "/usr/local/lib/python3.5/dist-packages/django/core/handlers/base.py", line 187, in _get_response
    response = self.process_exception_by_middleware(e, request)
  File "/usr/local/lib/python3.5/dist-packages/django/core/handlers/base.py", line 185, in _get_response
    response = wrapped_callback(request, *callback_args, **callback_kwargs)
  File "/home/tarena/PycharmProjects/StockProject/index/views.py", line 17, in index
    return render(req,'index.html')
  File "/usr/local/lib/python3.5/dist-packages/django/shortcuts.py", line 30, in render
    content = loader.render_to_string(template_name, context, request, using=using)
  File "/usr/local/lib/python3.5/dist-packages/django/template/loader.py", line 68, in render_to_string
    return template.render(context, request)
  File "/usr/local/lib/python3.5/dist-packages/django/template/backends/django.py", line 66, in render
    return self.template.render(context)
  File "/usr/local/lib/python3.5/dist-packages/django/template/base.py", line 207, in render
    return self._render(context)
  File "/usr/local/lib/python3.5/dist-packages/django/template/base.py", line 199, in _render
    return self.nodelist.render(context)
  File "/usr/local/lib/python3.5/dist-packages/django/template/base.py", line 990, in render
    bit = node.render_annotated(context)
  File "/usr/local/lib/python3.5/dist-packages/django/template/base.py", line 957, in render_annotated
    return self.render(context)
  File "/usr/local/lib/python3.5/dist-packages/django/template/loader_tags.py", line 177, in render
    return compiled_parent._render(context)
  File "/usr/local/lib/python3.5/dist-packages/django/template/base.py", line 199, in _render
    return self.nodelist.render(context)
  File "/usr/local/lib/python3.5/dist-packages/django/template/base.py", line 990, in render
    bit = node.render_annotated(context)
  File "/usr/local/lib/python3.5/dist-packages/django/template/base.py", line 957, in render_annotated
    return self.render(context)
  File "/usr/local/lib/python3.5/dist-packages/django/template/defaulttags.py", line 458, in render
    url = reverse(view_name, args=args, kwargs=kwargs, current_app=current_app)
  File "/usr/local/lib/python3.5/dist-packages/django/urls/base.py", line 91, in reverse
    return force_text(iri_to_uri(resolver._reverse_with_prefix(view, prefix, *args, **kwargs)))
  File "/usr/local/lib/python3.5/dist-packages/django/urls/resolvers.py", line 497, in _reverse_with_prefix
    raise NoReverseMatch(msg)
django.urls.exceptions.NoReverseMatch: Reverse for 'userinfo/login/' not found. 'userinfo/login/' is not a valid view function or pattern name.
[2019-04-30 06:25:16,057][Thread-6:140253604398848][task_id:django.server][basehttp.py:124][ERROR]["GET / HTTP/1.1" 500 148181]
[2019-04-30 06:25:50,653][Thread-8:140253604398848][task_id:django.request][exception.py:135][ERROR][Internal Server Error: /]
Traceback (most recent call last):
  File "/usr/local/lib/python3.5/dist-packages/django/core/handlers/exception.py", line 41, in inner
    response = get_response(request)
  File "/usr/local/lib/python3.5/dist-packages/django/core/handlers/base.py", line 187, in _get_response
    response = self.process_exception_by_middleware(e, request)
  File "/usr/local/lib/python3.5/dist-packages/django/core/handlers/base.py", line 185, in _get_response
    response = wrapped_callback(request, *callback_args, **callback_kwargs)
  File "/home/tarena/PycharmProjects/StockProject/index/views.py", line 17, in index
    return render(req,'index.html')
  File "/usr/local/lib/python3.5/dist-packages/django/shortcuts.py", line 30, in render
    content = loader.render_to_string(template_name, context, request, using=using)
  File "/usr/local/lib/python3.5/dist-packages/django/template/loader.py", line 68, in render_to_string
    return template.render(context, request)
  File "/usr/local/lib/python3.5/dist-packages/django/template/backends/django.py", line 66, in render
    return self.template.render(context)
  File "/usr/local/lib/python3.5/dist-packages/django/template/base.py", line 207, in render
    return self._render(context)
  File "/usr/local/lib/python3.5/dist-packages/django/template/base.py", line 199, in _render
    return self.nodelist.render(context)
  File "/usr/local/lib/python3.5/dist-packages/django/template/base.py", line 990, in render
    bit = node.render_annotated(context)
  File "/usr/local/lib/python3.5/dist-packages/django/template/base.py", line 957, in render_annotated
    return self.render(context)
  File "/usr/local/lib/python3.5/dist-packages/django/template/loader_tags.py", line 177, in render
    return compiled_parent._render(context)
  File "/usr/local/lib/python3.5/dist-packages/django/template/base.py", line 199, in _render
    return self.nodelist.render(context)
  File "/usr/local/lib/python3.5/dist-packages/django/template/base.py", line 990, in render
    bit = node.render_annotated(context)
  File "/usr/local/lib/python3.5/dist-packages/django/template/base.py", line 957, in render_annotated
    return self.render(context)
  File "/usr/local/lib/python3.5/dist-packages/django/template/defaulttags.py", line 458, in render
    url = reverse(view_name, args=args, kwargs=kwargs, current_app=current_app)
  File "/usr/local/lib/python3.5/dist-packages/django/urls/base.py", line 91, in reverse
    return force_text(iri_to_uri(resolver._reverse_with_prefix(view, prefix, *args, **kwargs)))
  File "/usr/local/lib/python3.5/dist-packages/django/urls/resolvers.py", line 497, in _reverse_with_prefix
    raise NoReverseMatch(msg)
django.urls.exceptions.NoReverseMatch: Reverse for '/userinfo/login' not found. '/userinfo/login' is not a valid view function or pattern name.
[2019-04-30 06:25:50,852][Thread-8:140253604398848][task_id:django.server][basehttp.py:124][ERROR]["GET / HTTP/1.1" 500 148316]
[2019-04-30 06:26:03,996][Thread-10:140253596006144][task_id:django.request][exception.py:135][ERROR][Internal Server Error: /]
Traceback (most recent call last):
  File "/usr/local/lib/python3.5/dist-packages/django/core/handlers/exception.py", line 41, in inner
    response = get_response(request)
  File "/usr/local/lib/python3.5/dist-packages/django/core/handlers/base.py", line 187, in _get_response
    response = self.process_exception_by_middleware(e, request)
  File "/usr/local/lib/python3.5/dist-packages/django/core/handlers/base.py", line 185, in _get_response
    response = wrapped_callback(request, *callback_args, **callback_kwargs)
  File "/home/tarena/PycharmProjects/StockProject/index/views.py", line 17, in index
    return render(req,'index.html')
  File "/usr/local/lib/python3.5/dist-packages/django/shortcuts.py", line 30, in render
    content = loader.render_to_string(template_name, context, request, using=using)
  File "/usr/local/lib/python3.5/dist-packages/django/template/loader.py", line 68, in render_to_string
    return template.render(context, request)
  File "/usr/local/lib/python3.5/dist-packages/django/template/backends/django.py", line 66, in render
    return self.template.render(context)
  File "/usr/local/lib/python3.5/dist-packages/django/template/base.py", line 207, in render
    return self._render(context)
  File "/usr/local/lib/python3.5/dist-packages/django/template/base.py", line 199, in _render
    return self.nodelist.render(context)
  File "/usr/local/lib/python3.5/dist-packages/django/template/base.py", line 990, in render
    bit = node.render_annotated(context)
  File "/usr/local/lib/python3.5/dist-packages/django/template/base.py", line 957, in render_annotated
    return self.render(context)
  File "/usr/local/lib/python3.5/dist-packages/django/template/loader_tags.py", line 177, in render
    return compiled_parent._render(context)
  File "/usr/local/lib/python3.5/dist-packages/django/template/base.py", line 199, in _render
    return self.nodelist.render(context)
  File "/usr/local/lib/python3.5/dist-packages/django/template/base.py", line 990, in render
    bit = node.render_annotated(context)
  File "/usr/local/lib/python3.5/dist-packages/django/template/base.py", line 957, in render_annotated
    return self.render(context)
  File "/usr/local/lib/python3.5/dist-packages/django/template/defaulttags.py", line 458, in render
    url = reverse(view_name, args=args, kwargs=kwargs, current_app=current_app)
  File "/usr/local/lib/python3.5/dist-packages/django/urls/base.py", line 91, in reverse
    return force_text(iri_to_uri(resolver._reverse_with_prefix(view, prefix, *args, **kwargs)))
  File "/usr/local/lib/python3.5/dist-packages/django/urls/resolvers.py", line 497, in _reverse_with_prefix
    raise NoReverseMatch(msg)
django.urls.exceptions.NoReverseMatch: Reverse for 'userinfo/login' not found. 'userinfo/login' is not a valid view function or pattern name.
[2019-04-30 06:26:04,242][Thread-10:140253596006144][task_id:django.server][basehttp.py:124][ERROR]["GET / HTTP/1.1" 500 148294]
[2019-04-30 06:26:28,325][Thread-2:140158214260480][task_id:django.request][exception.py:135][ERROR][Internal Server Error: /]
Traceback (most recent call last):
  File "/usr/local/lib/python3.5/dist-packages/django/core/handlers/exception.py", line 41, in inner
    response = get_response(request)
  File "/usr/local/lib/python3.5/dist-packages/django/core/handlers/base.py", line 187, in _get_response
    response = self.process_exception_by_middleware(e, request)
  File "/usr/local/lib/python3.5/dist-packages/django/core/handlers/base.py", line 185, in _get_response
    response = wrapped_callback(request, *callback_args, **callback_kwargs)
  File "/home/tarena/PycharmProjects/StockProject/index/views.py", line 17, in index
    return render(req,'index.html')
  File "/usr/local/lib/python3.5/dist-packages/django/shortcuts.py", line 30, in render
    content = loader.render_to_string(template_name, context, request, using=using)
  File "/usr/local/lib/python3.5/dist-packages/django/template/loader.py", line 68, in render_to_string
    return template.render(context, request)
  File "/usr/local/lib/python3.5/dist-packages/django/template/backends/django.py", line 66, in render
    return self.template.render(context)
  File "/usr/local/lib/python3.5/dist-packages/django/template/base.py", line 207, in render
    return self._render(context)
  File "/usr/local/lib/python3.5/dist-packages/django/template/base.py", line 199, in _render
    return self.nodelist.render(context)
  File "/usr/local/lib/python3.5/dist-packages/django/template/base.py", line 990, in render
    bit = node.render_annotated(context)
  File "/usr/local/lib/python3.5/dist-packages/django/template/base.py", line 957, in render_annotated
    return self.render(context)
  File "/usr/local/lib/python3.5/dist-packages/django/template/loader_tags.py", line 177, in render
    return compiled_parent._render(context)
  File "/usr/local/lib/python3.5/dist-packages/django/template/base.py", line 199, in _render
    return self.nodelist.render(context)
  File "/usr/local/lib/python3.5/dist-packages/django/template/base.py", line 990, in render
    bit = node.render_annotated(context)
  File "/usr/local/lib/python3.5/dist-packages/django/template/base.py", line 957, in render_annotated
    return self.render(context)
  File "/usr/local/lib/python3.5/dist-packages/django/template/defaulttags.py", line 458, in render
    url = reverse(view_name, args=args, kwargs=kwargs, current_app=current_app)
  File "/usr/local/lib/python3.5/dist-packages/django/urls/base.py", line 91, in reverse
    return force_text(iri_to_uri(resolver._reverse_with_prefix(view, prefix, *args, **kwargs)))
  File "/usr/local/lib/python3.5/dist-packages/django/urls/resolvers.py", line 497, in _reverse_with_prefix
    raise NoReverseMatch(msg)
django.urls.exceptions.NoReverseMatch: Reverse for 'userinfo/login' not found. 'userinfo/login' is not a valid view function or pattern name.
[2019-04-30 06:26:28,404][Thread-2:140158214260480][task_id:django.server][basehttp.py:124][ERROR]["GET / HTTP/1.1" 500 148294]
[2019-04-30 06:26:37,205][Thread-3:140158137530112][task_id:django.request][exception.py:135][ERROR][Internal Server Error: /]
Traceback (most recent call last):
  File "/usr/local/lib/python3.5/dist-packages/django/core/handlers/exception.py", line 41, in inner
    response = get_response(request)
  File "/usr/local/lib/python3.5/dist-packages/django/core/handlers/base.py", line 187, in _get_response
    response = self.process_exception_by_middleware(e, request)
  File "/usr/local/lib/python3.5/dist-packages/django/core/handlers/base.py", line 185, in _get_response
    response = wrapped_callback(request, *callback_args, **callback_kwargs)
  File "/home/tarena/PycharmProjects/StockProject/index/views.py", line 17, in index
    return render(req,'index.html')
  File "/usr/local/lib/python3.5/dist-packages/django/shortcuts.py", line 30, in render
    content = loader.render_to_string(template_name, context, request, using=using)
  File "/usr/local/lib/python3.5/dist-packages/django/template/loader.py", line 68, in render_to_string
    return template.render(context, request)
  File "/usr/local/lib/python3.5/dist-packages/django/template/backends/django.py", line 66, in render
    return self.template.render(context)
  File "/usr/local/lib/python3.5/dist-packages/django/template/base.py", line 207, in render
    return self._render(context)
  File "/usr/local/lib/python3.5/dist-packages/django/template/base.py", line 199, in _render
    return self.nodelist.render(context)
  File "/usr/local/lib/python3.5/dist-packages/django/template/base.py", line 990, in render
    bit = node.render_annotated(context)
  File "/usr/local/lib/python3.5/dist-packages/django/template/base.py", line 957, in render_annotated
    return self.render(context)
  File "/usr/local/lib/python3.5/dist-packages/django/template/loader_tags.py", line 177, in render
    return compiled_parent._render(context)
  File "/usr/local/lib/python3.5/dist-packages/django/template/base.py", line 199, in _render
    return self.nodelist.render(context)
  File "/usr/local/lib/python3.5/dist-packages/django/template/base.py", line 990, in render
    bit = node.render_annotated(context)
  File "/usr/local/lib/python3.5/dist-packages/django/template/base.py", line 957, in render_annotated
    return self.render(context)
  File "/usr/local/lib/python3.5/dist-packages/django/template/defaulttags.py", line 458, in render
    url = reverse(view_name, args=args, kwargs=kwargs, current_app=current_app)
  File "/usr/local/lib/python3.5/dist-packages/django/urls/base.py", line 91, in reverse
    return force_text(iri_to_uri(resolver._reverse_with_prefix(view, prefix, *args, **kwargs)))
  File "/usr/local/lib/python3.5/dist-packages/django/urls/resolvers.py", line 497, in _reverse_with_prefix
    raise NoReverseMatch(msg)
django.urls.exceptions.NoReverseMatch: Reverse for 'userinfo/login/' not found. 'userinfo/login/' is not a valid view function or pattern name.
[2019-04-30 06:26:37,541][Thread-3:140158137530112][task_id:django.server][basehttp.py:124][ERROR]["GET / HTTP/1.1" 500 148319]
[2019-04-30 06:27:32,815][Thread-9:140158137530112][task_id:django.request][exception.py:135][ERROR][Internal Server Error: /]
Traceback (most recent call last):
  File "/usr/local/lib/python3.5/dist-packages/django/core/handlers/exception.py", line 41, in inner
    response = get_response(request)
  File "/usr/local/lib/python3.5/dist-packages/django/core/handlers/base.py", line 187, in _get_response
    response = self.process_exception_by_middleware(e, request)
  File "/usr/local/lib/python3.5/dist-packages/django/core/handlers/base.py", line 185, in _get_response
    response = wrapped_callback(request, *callback_args, **callback_kwargs)
  File "/home/tarena/PycharmProjects/StockProject/index/views.py", line 17, in index
    return render(req,'index.html')
  File "/usr/local/lib/python3.5/dist-packages/django/shortcuts.py", line 30, in render
    content = loader.render_to_string(template_name, context, request, using=using)
  File "/usr/local/lib/python3.5/dist-packages/django/template/loader.py", line 68, in render_to_string
    return template.render(context, request)
  File "/usr/local/lib/python3.5/dist-packages/django/template/backends/django.py", line 66, in render
    return self.template.render(context)
  File "/usr/local/lib/python3.5/dist-packages/django/template/base.py", line 207, in render
    return self._render(context)
  File "/usr/local/lib/python3.5/dist-packages/django/template/base.py", line 199, in _render
    return self.nodelist.render(context)
  File "/usr/local/lib/python3.5/dist-packages/django/template/base.py", line 990, in render
    bit = node.render_annotated(context)
  File "/usr/local/lib/python3.5/dist-packages/django/template/base.py", line 957, in render_annotated
    return self.render(context)
  File "/usr/local/lib/python3.5/dist-packages/django/template/loader_tags.py", line 177, in render
    return compiled_parent._render(context)
  File "/usr/local/lib/python3.5/dist-packages/django/template/base.py", line 199, in _render
    return self.nodelist.render(context)
  File "/usr/local/lib/python3.5/dist-packages/django/template/base.py", line 990, in render
    bit = node.render_annotated(context)
  File "/usr/local/lib/python3.5/dist-packages/django/template/base.py", line 957, in render_annotated
    return self.render(context)
  File "/usr/local/lib/python3.5/dist-packages/django/template/defaulttags.py", line 458, in render
    url = reverse(view_name, args=args, kwargs=kwargs, current_app=current_app)
  File "/usr/local/lib/python3.5/dist-packages/django/urls/base.py", line 91, in reverse
    return force_text(iri_to_uri(resolver._reverse_with_prefix(view, prefix, *args, **kwargs)))
  File "/usr/local/lib/python3.5/dist-packages/django/urls/resolvers.py", line 497, in _reverse_with_prefix
    raise NoReverseMatch(msg)
django.urls.exceptions.NoReverseMatch: Reverse for 'login/' not found. 'login/' is not a valid view function or pattern name.
[2019-04-30 06:27:33,036][Thread-9:140158137530112][task_id:django.server][basehttp.py:124][ERROR]["GET / HTTP/1.1" 500 147985]
[2019-04-30 06:27:38,970][Thread-11:140158214260480][task_id:django.request][exception.py:135][ERROR][Internal Server Error: /]
Traceback (most recent call last):
  File "/usr/local/lib/python3.5/dist-packages/django/core/handlers/exception.py", line 41, in inner
    response = get_response(request)
  File "/usr/local/lib/python3.5/dist-packages/django/core/handlers/base.py", line 187, in _get_response
    response = self.process_exception_by_middleware(e, request)
  File "/usr/local/lib/python3.5/dist-packages/django/core/handlers/base.py", line 185, in _get_response
    response = wrapped_callback(request, *callback_args, **callback_kwargs)
  File "/home/tarena/PycharmProjects/StockProject/index/views.py", line 17, in index
    return render(req,'index.html')
  File "/usr/local/lib/python3.5/dist-packages/django/shortcuts.py", line 30, in render
    content = loader.render_to_string(template_name, context, request, using=using)
  File "/usr/local/lib/python3.5/dist-packages/django/template/loader.py", line 68, in render_to_string
    return template.render(context, request)
  File "/usr/local/lib/python3.5/dist-packages/django/template/backends/django.py", line 66, in render
    return self.template.render(context)
  File "/usr/local/lib/python3.5/dist-packages/django/template/base.py", line 207, in render
    return self._render(context)
  File "/usr/local/lib/python3.5/dist-packages/django/template/base.py", line 199, in _render
    return self.nodelist.render(context)
  File "/usr/local/lib/python3.5/dist-packages/django/template/base.py", line 990, in render
    bit = node.render_annotated(context)
  File "/usr/local/lib/python3.5/dist-packages/django/template/base.py", line 957, in render_annotated
    return self.render(context)
  File "/usr/local/lib/python3.5/dist-packages/django/template/loader_tags.py", line 177, in render
    return compiled_parent._render(context)
  File "/usr/local/lib/python3.5/dist-packages/django/template/base.py", line 199, in _render
    return self.nodelist.render(context)
  File "/usr/local/lib/python3.5/dist-packages/django/template/base.py", line 990, in render
    bit = node.render_annotated(context)
  File "/usr/local/lib/python3.5/dist-packages/django/template/base.py", line 957, in render_annotated
    return self.render(context)
  File "/usr/local/lib/python3.5/dist-packages/django/template/defaulttags.py", line 458, in render
    url = reverse(view_name, args=args, kwargs=kwargs, current_app=current_app)
  File "/usr/local/lib/python3.5/dist-packages/django/urls/base.py", line 91, in reverse
    return force_text(iri_to_uri(resolver._reverse_with_prefix(view, prefix, *args, **kwargs)))
  File "/usr/local/lib/python3.5/dist-packages/django/urls/resolvers.py", line 497, in _reverse_with_prefix
    raise NoReverseMatch(msg)
django.urls.exceptions.NoReverseMatch: Reverse for 'userinfo/register/' not found. 'userinfo/register/' is not a valid view function or pattern name.
[2019-04-30 06:27:39,157][Thread-11:140158214260480][task_id:django.server][basehttp.py:124][ERROR]["GET / HTTP/1.1" 500 148170]
[2019-04-30 06:27:46,030][Thread-12:140158137530112][task_id:django.request][exception.py:135][ERROR][Internal Server Error: /]
Traceback (most recent call last):
  File "/usr/local/lib/python3.5/dist-packages/django/core/handlers/exception.py", line 41, in inner
    response = get_response(request)
  File "/usr/local/lib/python3.5/dist-packages/django/core/handlers/base.py", line 187, in _get_response
    response = self.process_exception_by_middleware(e, request)
  File "/usr/local/lib/python3.5/dist-packages/django/core/handlers/base.py", line 185, in _get_response
    response = wrapped_callback(request, *callback_args, **callback_kwargs)
  File "/home/tarena/PycharmProjects/StockProject/index/views.py", line 17, in index
    return render(req,'index.html')
  File "/usr/local/lib/python3.5/dist-packages/django/shortcuts.py", line 30, in render
    content = loader.render_to_string(template_name, context, request, using=using)
  File "/usr/local/lib/python3.5/dist-packages/django/template/loader.py", line 68, in render_to_string
    return template.render(context, request)
  File "/usr/local/lib/python3.5/dist-packages/django/template/backends/django.py", line 66, in render
    return self.template.render(context)
  File "/usr/local/lib/python3.5/dist-packages/django/template/base.py", line 207, in render
    return self._render(context)
  File "/usr/local/lib/python3.5/dist-packages/django/template/base.py", line 199, in _render
    return self.nodelist.render(context)
  File "/usr/local/lib/python3.5/dist-packages/django/template/base.py", line 990, in render
    bit = node.render_annotated(context)
  File "/usr/local/lib/python3.5/dist-packages/django/template/base.py", line 957, in render_annotated
    return self.render(context)
  File "/usr/local/lib/python3.5/dist-packages/django/template/loader_tags.py", line 177, in render
    return compiled_parent._render(context)
  File "/usr/local/lib/python3.5/dist-packages/django/template/base.py", line 199, in _render
    return self.nodelist.render(context)
  File "/usr/local/lib/python3.5/dist-packages/django/template/base.py", line 990, in render
    bit = node.render_annotated(context)
  File "/usr/local/lib/python3.5/dist-packages/django/template/base.py", line 957, in render_annotated
    return self.render(context)
  File "/usr/local/lib/python3.5/dist-packages/django/template/defaulttags.py", line 458, in render
    url = reverse(view_name, args=args, kwargs=kwargs, current_app=current_app)
  File "/usr/local/lib/python3.5/dist-packages/django/urls/base.py", line 91, in reverse
    return force_text(iri_to_uri(resolver._reverse_with_prefix(view, prefix, *args, **kwargs)))
  File "/usr/local/lib/python3.5/dist-packages/django/urls/resolvers.py", line 497, in _reverse_with_prefix
    raise NoReverseMatch(msg)
django.urls.exceptions.NoReverseMatch: Reverse for 'usercenter' not found. 'usercenter' is not a valid view function or pattern name.
[2019-04-30 06:27:46,469][Thread-12:140158137530112][task_id:django.server][basehttp.py:124][ERROR]["GET / HTTP/1.1" 500 148736]
[2019-04-30 09:50:31,677][Thread-8:140202286012160][task_id:django.request][exception.py:135][ERROR][Internal Server Error: /stock_basics/]
Traceback (most recent call last):
  File "/usr/local/lib/python3.5/dist-packages/django/core/handlers/exception.py", line 41, in inner
    response = get_response(request)
  File "/usr/local/lib/python3.5/dist-packages/django/core/handlers/base.py", line 198, in _get_response
    "returned None instead." % (callback.__module__, view_name)
ValueError: The view index.views.stock_basics didn't return an HttpResponse object. It returned None instead.
[2019-04-30 09:50:32,036][Thread-8:140202286012160][task_id:django.server][basehttp.py:124][ERROR]["GET /stock_basics/ HTTP/1.1" 500 18308]
[2019-05-02 15:30:52,786][Thread-21:139973235824384][task_id:django.request][base.py:284][ERROR][Internal Server Error: /stock_basics/]
Traceback (most recent call last):
  File "/home/kudoxi/.local/lib/python3.5/site-packages/django/core/handlers/base.py", line 149, in get_response
    response = self.process_exception_by_middleware(e, request)
  File "/home/kudoxi/.local/lib/python3.5/site-packages/django/core/handlers/base.py", line 147, in get_response
    response = wrapped_callback(request, *callback_args, **callback_kwargs)
  File "/home/kudoxi/PycharmProjects/StockWeb/index/views.py", line 21, in stock_basics
    print(df.head(),type(df),df.info())
AttributeError: 'NoneType' object has no attribute 'head'
[2019-05-02 16:16:05,865][Thread-4:139809087506176][task_id:django.request][base.py:284][ERROR][Internal Server Error: /stock_basics/]
Traceback (most recent call last):
  File "/home/kudoxi/.local/lib/python3.5/site-packages/django/core/handlers/base.py", line 149, in get_response
    response = self.process_exception_by_middleware(e, request)
  File "/home/kudoxi/.local/lib/python3.5/site-packages/django/core/handlers/base.py", line 147, in get_response
    response = wrapped_callback(request, *callback_args, **callback_kwargs)
  File "/home/kudoxi/PycharmProjects/StockWeb/index/views.py", line 31, in stock_basics
    logging.getLogger('df.head():',df.head())
TypeError: getLogger() takes from 0 to 1 positional arguments but 2 were given
[2019-05-02 16:17:28,175][Thread-3:140115254966016][task_id:django.request][base.py:284][ERROR][Internal Server Error: /stock_basics/]
Traceback (most recent call last):
  File "/home/kudoxi/.local/lib/python3.5/site-packages/django/core/handlers/base.py", line 149, in get_response
    response = self.process_exception_by_middleware(e, request)
  File "/home/kudoxi/.local/lib/python3.5/site-packages/django/core/handlers/base.py", line 147, in get_response
    response = wrapped_callback(request, *callback_args, **callback_kwargs)
  File "/home/kudoxi/PycharmProjects/StockWeb/index/views.py", line 31, in stock_basics
    logging.getLogger(df.head())
  File "/usr/lib/python3.5/logging/__init__.py", line 1780, in getLogger
    if name:
  File "/home/kudoxi/.local/lib/python3.5/site-packages/pandas/core/generic.py", line 1478, in __nonzero__
    .format(self.__class__.__name__))
ValueError: The truth value of a DataFrame is ambiguous. Use a.empty, a.bool(), a.item(), a.any() or a.all().
[2019-05-02 16:18:49,575][Thread-3:140591256442624][task_id:django.request][base.py:284][ERROR][Internal Server Error: /stock_basics/]
Traceback (most recent call last):
  File "/home/kudoxi/.local/lib/python3.5/site-packages/django/core/handlers/base.py", line 149, in get_response
    response = self.process_exception_by_middleware(e, request)
  File "/home/kudoxi/.local/lib/python3.5/site-packages/django/core/handlers/base.py", line 147, in get_response
    response = wrapped_callback(request, *callback_args, **callback_kwargs)
  File "/home/kudoxi/PycharmProjects/StockWeb/index/views.py", line 31, in stock_basics
    if df:
  File "/home/kudoxi/.local/lib/python3.5/site-packages/pandas/core/generic.py", line 1478, in __nonzero__
    .format(self.__class__.__name__))
ValueError: The truth value of a DataFrame is ambiguous. Use a.empty, a.bool(), a.item(), a.any() or a.all().
[2019-05-02 16:22:38,306][Thread-3:140594685945600][task_id:django.request][base.py:284][ERROR][Internal Server Error: /stock_basics/]
Traceback (most recent call last):
  File "/home/kudoxi/.local/lib/python3.5/site-packages/django/core/handlers/base.py", line 149, in get_response
    response = self.process_exception_by_middleware(e, request)
  File "/home/kudoxi/.local/lib/python3.5/site-packages/django/core/handlers/base.py", line 147, in get_response
    response = wrapped_callback(request, *callback_args, **callback_kwargs)
  File "/home/kudoxi/PycharmProjects/StockWeb/index/views.py", line 31, in stock_basics
    if df:
  File "/home/kudoxi/.local/lib/python3.5/site-packages/pandas/core/generic.py", line 1478, in __nonzero__
    .format(self.__class__.__name__))
ValueError: The truth value of a DataFrame is ambiguous. Use a.empty, a.bool(), a.item(), a.any() or a.all().
[2019-05-02 16:23:12,159][Thread-3:140313104385792][task_id:django.request][base.py:284][ERROR][Internal Server Error: /stock_basics/]
Traceback (most recent call last):
  File "/home/kudoxi/.local/lib/python3.5/site-packages/django/core/handlers/base.py", line 149, in get_response
    response = self.process_exception_by_middleware(e, request)
  File "/home/kudoxi/.local/lib/python3.5/site-packages/django/core/handlers/base.py", line 147, in get_response
    response = wrapped_callback(request, *callback_args, **callback_kwargs)
  File "/home/kudoxi/PycharmProjects/StockWeb/index/views.py", line 31, in stock_basics
    if not df.empty:
  File "/home/kudoxi/.local/lib/python3.5/site-packages/pandas/core/generic.py", line 1478, in __nonzero__
    .format(self.__class__.__name__))
ValueError: The truth value of a DataFrame is ambiguous. Use a.empty, a.bool(), a.item(), a.any() or a.all().
[2019-05-02 16:23:47,106][Thread-3:139799601731328][task_id:django.request][base.py:284][ERROR][Internal Server Error: /stock_basics/]
Traceback (most recent call last):
  File "/home/kudoxi/.local/lib/python3.5/site-packages/django/core/handlers/base.py", line 149, in get_response
    response = self.process_exception_by_middleware(e, request)
  File "/home/kudoxi/.local/lib/python3.5/site-packages/django/core/handlers/base.py", line 147, in get_response
    response = wrapped_callback(request, *callback_args, **callback_kwargs)
  File "/home/kudoxi/PycharmProjects/StockWeb/index/views.py", line 35, in stock_basics
    return HttpResponse(json.dump(params))
TypeError: dump() missing 1 required positional argument: 'fp'
[2019-05-02 16:26:29,871][Thread-3:140141024769792][task_id:django.request][base.py:284][ERROR][Internal Server Error: /stock_basics/]
Traceback (most recent call last):
  File "/home/kudoxi/.local/lib/python3.5/site-packages/django/core/handlers/base.py", line 149, in get_response
    response = self.process_exception_by_middleware(e, request)
  File "/home/kudoxi/.local/lib/python3.5/site-packages/django/core/handlers/base.py", line 147, in get_response
    response = wrapped_callback(request, *callback_args, **callback_kwargs)
  File "/home/kudoxi/PycharmProjects/StockWeb/index/views.py", line 35, in stock_basics
    return HttpResponse(json.dump(params,ensure_ascii=False))
TypeError: dump() missing 1 required positional argument: 'fp'
[2019-05-02 16:34:47,668][Thread-3:139654468314880][task_id:django.request][base.py:284][ERROR][Internal Server Error: /]
Traceback (most recent call last):
  File "/home/kudoxi/.local/lib/python3.5/site-packages/django/template/defaulttags.py", line 507, in render
    current_app=current_app)
  File "/home/kudoxi/.local/lib/python3.5/site-packages/django/core/urlresolvers.py", line 600, in reverse
    return force_text(iri_to_uri(resolver._reverse_with_prefix(view, prefix, *args, **kwargs)))
  File "/home/kudoxi/.local/lib/python3.5/site-packages/django/core/urlresolvers.py", line 508, in _reverse_with_prefix
    (lookup_view_s, args, kwargs, len(patterns), patterns))
django.core.urlresolvers.NoReverseMatch: Reverse for 'StockProject.?code=0000' with arguments '()' and keyword arguments '{}' not found. 0 pattern(s) tried: []

During handling of the above exception, another exception occurred:

Traceback (most recent call last):
  File "/home/kudoxi/.local/lib/python3.5/site-packages/django/core/handlers/base.py", line 149, in get_response
    response = self.process_exception_by_middleware(e, request)
  File "/home/kudoxi/.local/lib/python3.5/site-packages/django/core/handlers/base.py", line 147, in get_response
    response = wrapped_callback(request, *callback_args, **callback_kwargs)
  File "/home/kudoxi/PycharmProjects/StockWeb/index/views.py", line 15, in index
    return render(req,'index.html')
  File "/home/kudoxi/.local/lib/python3.5/site-packages/django/shortcuts.py", line 67, in render
    template_name, context, request=request, using=using)
  File "/home/kudoxi/.local/lib/python3.5/site-packages/django/template/loader.py", line 97, in render_to_string
    return template.render(context, request)
  File "/home/kudoxi/.local/lib/python3.5/site-packages/django/template/backends/django.py", line 95, in render
    return self.template.render(context)
  File "/home/kudoxi/.local/lib/python3.5/site-packages/django/template/base.py", line 206, in render
    return self._render(context)
  File "/home/kudoxi/.local/lib/python3.5/site-packages/django/template/base.py", line 197, in _render
    return self.nodelist.render(context)
  File "/home/kudoxi/.local/lib/python3.5/site-packages/django/template/base.py", line 988, in render
    bit = node.render_annotated(context)
  File "/home/kudoxi/.local/lib/python3.5/site-packages/django/template/base.py", line 955, in render_annotated
    return self.render(context)
  File "/home/kudoxi/.local/lib/python3.5/site-packages/django/template/loader_tags.py", line 173, in render
    return compiled_parent._render(context)
  File "/home/kudoxi/.local/lib/python3.5/site-packages/django/template/base.py", line 197, in _render
    return self.nodelist.render(context)
  File "/home/kudoxi/.local/lib/python3.5/site-packages/django/template/base.py", line 988, in render
    bit = node.render_annotated(context)
  File "/home/kudoxi/.local/lib/python3.5/site-packages/django/template/base.py", line 955, in render_annotated
    return self.render(context)
  File "/home/kudoxi/.local/lib/python3.5/site-packages/django/template/loader_tags.py", line 69, in render
    result = block.nodelist.render(context)
  File "/home/kudoxi/.local/lib/python3.5/site-packages/django/template/base.py", line 988, in render
    bit = node.render_annotated(context)
  File "/home/kudoxi/.local/lib/python3.5/site-packages/django/template/base.py", line 955, in render_annotated
    return self.render(context)
  File "/home/kudoxi/.local/lib/python3.5/site-packages/django/template/defaulttags.py", line 513, in render
    six.reraise(*exc_info)
  File "/home/kudoxi/.local/lib/python3.5/site-packages/django/utils/six.py", line 686, in reraise
    raise value
  File "/home/kudoxi/.local/lib/python3.5/site-packages/django/template/defaulttags.py", line 499, in render
    url = reverse(view_name, args=args, kwargs=kwargs, current_app=current_app)
  File "/home/kudoxi/.local/lib/python3.5/site-packages/django/core/urlresolvers.py", line 600, in reverse
    return force_text(iri_to_uri(resolver._reverse_with_prefix(view, prefix, *args, **kwargs)))
  File "/home/kudoxi/.local/lib/python3.5/site-packages/django/core/urlresolvers.py", line 508, in _reverse_with_prefix
    (lookup_view_s, args, kwargs, len(patterns), patterns))
django.core.urlresolvers.NoReverseMatch: Reverse for '?code=0000' with arguments '()' and keyword arguments '{}' not found. 0 pattern(s) tried: []
[2019-05-02 16:36:17,829][Thread-5:139654452430592][task_id:django.request][base.py:284][ERROR][Internal Server Error: /]
Traceback (most recent call last):
  File "/home/kudoxi/.local/lib/python3.5/site-packages/django/template/defaulttags.py", line 507, in render
    current_app=current_app)
  File "/home/kudoxi/.local/lib/python3.5/site-packages/django/core/urlresolvers.py", line 600, in reverse
    return force_text(iri_to_uri(resolver._reverse_with_prefix(view, prefix, *args, **kwargs)))
  File "/home/kudoxi/.local/lib/python3.5/site-packages/django/core/urlresolvers.py", line 508, in _reverse_with_prefix
    (lookup_view_s, args, kwargs, len(patterns), patterns))
django.core.urlresolvers.NoReverseMatch: Reverse for 'StockProject./?code=0000' with arguments '()' and keyword arguments '{}' not found. 0 pattern(s) tried: []

During handling of the above exception, another exception occurred:

Traceback (most recent call last):
  File "/home/kudoxi/.local/lib/python3.5/site-packages/django/core/handlers/base.py", line 149, in get_response
    response = self.process_exception_by_middleware(e, request)
  File "/home/kudoxi/.local/lib/python3.5/site-packages/django/core/handlers/base.py", line 147, in get_response
    response = wrapped_callback(request, *callback_args, **callback_kwargs)
  File "/home/kudoxi/PycharmProjects/StockWeb/index/views.py", line 15, in index
    return render(req,'index.html')
  File "/home/kudoxi/.local/lib/python3.5/site-packages/django/shortcuts.py", line 67, in render
    template_name, context, request=request, using=using)
  File "/home/kudoxi/.local/lib/python3.5/site-packages/django/template/loader.py", line 97, in render_to_string
    return template.render(context, request)
  File "/home/kudoxi/.local/lib/python3.5/site-packages/django/template/backends/django.py", line 95, in render
    return self.template.render(context)
  File "/home/kudoxi/.local/lib/python3.5/site-packages/django/template/base.py", line 206, in render
    return self._render(context)
  File "/home/kudoxi/.local/lib/python3.5/site-packages/django/template/base.py", line 197, in _render
    return self.nodelist.render(context)
  File "/home/kudoxi/.local/lib/python3.5/site-packages/django/template/base.py", line 988, in render
    bit = node.render_annotated(context)
  File "/home/kudoxi/.local/lib/python3.5/site-packages/django/template/base.py", line 955, in render_annotated
    return self.render(context)
  File "/home/kudoxi/.local/lib/python3.5/site-packages/django/template/loader_tags.py", line 173, in render
    return compiled_parent._render(context)
  File "/home/kudoxi/.local/lib/python3.5/site-packages/django/template/base.py", line 197, in _render
    return self.nodelist.render(context)
  File "/home/kudoxi/.local/lib/python3.5/site-packages/django/template/base.py", line 988, in render
    bit = node.render_annotated(context)
  File "/home/kudoxi/.local/lib/python3.5/site-packages/django/template/base.py", line 955, in render_annotated
    return self.render(context)
  File "/home/kudoxi/.local/lib/python3.5/site-packages/django/template/loader_tags.py", line 69, in render
    result = block.nodelist.render(context)
  File "/home/kudoxi/.local/lib/python3.5/site-packages/django/template/base.py", line 988, in render
    bit = node.render_annotated(context)
  File "/home/kudoxi/.local/lib/python3.5/site-packages/django/template/base.py", line 955, in render_annotated
    return self.render(context)
  File "/home/kudoxi/.local/lib/python3.5/site-packages/django/template/defaulttags.py", line 513, in render
    six.reraise(*exc_info)
  File "/home/kudoxi/.local/lib/python3.5/site-packages/django/utils/six.py", line 686, in reraise
    raise value
  File "/home/kudoxi/.local/lib/python3.5/site-packages/django/template/defaulttags.py", line 499, in render
    url = reverse(view_name, args=args, kwargs=kwargs, current_app=current_app)
  File "/home/kudoxi/.local/lib/python3.5/site-packages/django/core/urlresolvers.py", line 600, in reverse
    return force_text(iri_to_uri(resolver._reverse_with_prefix(view, prefix, *args, **kwargs)))
  File "/home/kudoxi/.local/lib/python3.5/site-packages/django/core/urlresolvers.py", line 508, in _reverse_with_prefix
    (lookup_view_s, args, kwargs, len(patterns), patterns))
django.core.urlresolvers.NoReverseMatch: Reverse for '/?code=0000' with arguments '()' and keyword arguments '{}' not found. 0 pattern(s) tried: []
[2019-05-02 16:36:24,570][Thread-6:139654468314880][task_id:django.request][base.py:284][ERROR][Internal Server Error: /]
Traceback (most recent call last):
  File "/home/kudoxi/.local/lib/python3.5/site-packages/django/template/defaulttags.py", line 507, in render
    current_app=current_app)
  File "/home/kudoxi/.local/lib/python3.5/site-packages/django/core/urlresolvers.py", line 600, in reverse
    return force_text(iri_to_uri(resolver._reverse_with_prefix(view, prefix, *args, **kwargs)))
  File "/home/kudoxi/.local/lib/python3.5/site-packages/django/core/urlresolvers.py", line 508, in _reverse_with_prefix
    (lookup_view_s, args, kwargs, len(patterns), patterns))
django.core.urlresolvers.NoReverseMatch: Reverse for 'StockProject./' with arguments '()' and keyword arguments '{}' not found. 0 pattern(s) tried: []

During handling of the above exception, another exception occurred:

Traceback (most recent call last):
  File "/home/kudoxi/.local/lib/python3.5/site-packages/django/core/handlers/base.py", line 149, in get_response
    response = self.process_exception_by_middleware(e, request)
  File "/home/kudoxi/.local/lib/python3.5/site-packages/django/core/handlers/base.py", line 147, in get_response
    response = wrapped_callback(request, *callback_args, **callback_kwargs)
  File "/home/kudoxi/PycharmProjects/StockWeb/index/views.py", line 15, in index
    return render(req,'index.html')
  File "/home/kudoxi/.local/lib/python3.5/site-packages/django/shortcuts.py", line 67, in render
    template_name, context, request=request, using=using)
  File "/home/kudoxi/.local/lib/python3.5/site-packages/django/template/loader.py", line 97, in render_to_string
    return template.render(context, request)
  File "/home/kudoxi/.local/lib/python3.5/site-packages/django/template/backends/django.py", line 95, in render
    return self.template.render(context)
  File "/home/kudoxi/.local/lib/python3.5/site-packages/django/template/base.py", line 206, in render
    return self._render(context)
  File "/home/kudoxi/.local/lib/python3.5/site-packages/django/template/base.py", line 197, in _render
    return self.nodelist.render(context)
  File "/home/kudoxi/.local/lib/python3.5/site-packages/django/template/base.py", line 988, in render
    bit = node.render_annotated(context)
  File "/home/kudoxi/.local/lib/python3.5/site-packages/django/template/base.py", line 955, in render_annotated
    return self.render(context)
  File "/home/kudoxi/.local/lib/python3.5/site-packages/django/template/loader_tags.py", line 173, in render
    return compiled_parent._render(context)
  File "/home/kudoxi/.local/lib/python3.5/site-packages/django/template/base.py", line 197, in _render
    return self.nodelist.render(context)
  File "/home/kudoxi/.local/lib/python3.5/site-packages/django/template/base.py", line 988, in render
    bit = node.render_annotated(context)
  File "/home/kudoxi/.local/lib/python3.5/site-packages/django/template/base.py", line 955, in render_annotated
    return self.render(context)
  File "/home/kudoxi/.local/lib/python3.5/site-packages/django/template/loader_tags.py", line 69, in render
    result = block.nodelist.render(context)
  File "/home/kudoxi/.local/lib/python3.5/site-packages/django/template/base.py", line 988, in render
    bit = node.render_annotated(context)
  File "/home/kudoxi/.local/lib/python3.5/site-packages/django/template/base.py", line 955, in render_annotated
    return self.render(context)
  File "/home/kudoxi/.local/lib/python3.5/site-packages/django/template/defaulttags.py", line 513, in render
    six.reraise(*exc_info)
  File "/home/kudoxi/.local/lib/python3.5/site-packages/django/utils/six.py", line 686, in reraise
    raise value
  File "/home/kudoxi/.local/lib/python3.5/site-packages/django/template/defaulttags.py", line 499, in render
    url = reverse(view_name, args=args, kwargs=kwargs, current_app=current_app)
  File "/home/kudoxi/.local/lib/python3.5/site-packages/django/core/urlresolvers.py", line 600, in reverse
    return force_text(iri_to_uri(resolver._reverse_with_prefix(view, prefix, *args, **kwargs)))
  File "/home/kudoxi/.local/lib/python3.5/site-packages/django/core/urlresolvers.py", line 508, in _reverse_with_prefix
    (lookup_view_s, args, kwargs, len(patterns), patterns))
django.core.urlresolvers.NoReverseMatch: Reverse for '/' with arguments '()' and keyword arguments '{}' not found. 0 pattern(s) tried: []
[2019-05-02 16:36:58,896][Thread-8:139654452430592][task_id:django.request][base.py:284][ERROR][Internal Server Error: /]
Traceback (most recent call last):
  File "/home/kudoxi/.local/lib/python3.5/site-packages/django/template/defaulttags.py", line 507, in render
    current_app=current_app)
  File "/home/kudoxi/.local/lib/python3.5/site-packages/django/core/urlresolvers.py", line 600, in reverse
    return force_text(iri_to_uri(resolver._reverse_with_prefix(view, prefix, *args, **kwargs)))
  File "/home/kudoxi/.local/lib/python3.5/site-packages/django/core/urlresolvers.py", line 508, in _reverse_with_prefix
    (lookup_view_s, args, kwargs, len(patterns), patterns))
django.core.urlresolvers.NoReverseMatch: Reverse for 'StockProject.index?code=0000' with arguments '()' and keyword arguments '{}' not found. 0 pattern(s) tried: []

During handling of the above exception, another exception occurred:

Traceback (most recent call last):
  File "/home/kudoxi/.local/lib/python3.5/site-packages/django/core/handlers/base.py", line 149, in get_response
    response = self.process_exception_by_middleware(e, request)
  File "/home/kudoxi/.local/lib/python3.5/site-packages/django/core/handlers/base.py", line 147, in get_response
    response = wrapped_callback(request, *callback_args, **callback_kwargs)
  File "/home/kudoxi/PycharmProjects/StockWeb/index/views.py", line 15, in index
    return render(req,'index.html')
  File "/home/kudoxi/.local/lib/python3.5/site-packages/django/shortcuts.py", line 67, in render
    template_name, context, request=request, using=using)
  File "/home/kudoxi/.local/lib/python3.5/site-packages/django/template/loader.py", line 97, in render_to_string
    return template.render(context, request)
  File "/home/kudoxi/.local/lib/python3.5/site-packages/django/template/backends/django.py", line 95, in render
    return self.template.render(context)
  File "/home/kudoxi/.local/lib/python3.5/site-packages/django/template/base.py", line 206, in render
    return self._render(context)
  File "/home/kudoxi/.local/lib/python3.5/site-packages/django/template/base.py", line 197, in _render
    return self.nodelist.render(context)
  File "/home/kudoxi/.local/lib/python3.5/site-packages/django/template/base.py", line 988, in render
    bit = node.render_annotated(context)
  File "/home/kudoxi/.local/lib/python3.5/site-packages/django/template/base.py", line 955, in render_annotated
    return self.render(context)
  File "/home/kudoxi/.local/lib/python3.5/site-packages/django/template/loader_tags.py", line 173, in render
    return compiled_parent._render(context)
  File "/home/kudoxi/.local/lib/python3.5/site-packages/django/template/base.py", line 197, in _render
    return self.nodelist.render(context)
  File "/home/kudoxi/.local/lib/python3.5/site-packages/django/template/base.py", line 988, in render
    bit = node.render_annotated(context)
  File "/home/kudoxi/.local/lib/python3.5/site-packages/django/template/base.py", line 955, in render_annotated
    return self.render(context)
  File "/home/kudoxi/.local/lib/python3.5/site-packages/django/template/loader_tags.py", line 69, in render
    result = block.nodelist.render(context)
  File "/home/kudoxi/.local/lib/python3.5/site-packages/django/template/base.py", line 988, in render
    bit = node.render_annotated(context)
  File "/home/kudoxi/.local/lib/python3.5/site-packages/django/template/base.py", line 955, in render_annotated
    return self.render(context)
  File "/home/kudoxi/.local/lib/python3.5/site-packages/django/template/defaulttags.py", line 513, in render
    six.reraise(*exc_info)
  File "/home/kudoxi/.local/lib/python3.5/site-packages/django/utils/six.py", line 686, in reraise
    raise value
  File "/home/kudoxi/.local/lib/python3.5/site-packages/django/template/defaulttags.py", line 499, in render
    url = reverse(view_name, args=args, kwargs=kwargs, current_app=current_app)
  File "/home/kudoxi/.local/lib/python3.5/site-packages/django/core/urlresolvers.py", line 600, in reverse
    return force_text(iri_to_uri(resolver._reverse_with_prefix(view, prefix, *args, **kwargs)))
  File "/home/kudoxi/.local/lib/python3.5/site-packages/django/core/urlresolvers.py", line 508, in _reverse_with_prefix
    (lookup_view_s, args, kwargs, len(patterns), patterns))
django.core.urlresolvers.NoReverseMatch: Reverse for 'index?code=0000' with arguments '()' and keyword arguments '{}' not found. 0 pattern(s) tried: []
[2019-05-02 16:38:54,106][Thread-10:139654468314880][task_id:django.request][base.py:284][ERROR][Internal Server Error: /]
Traceback (most recent call last):
  File "/home/kudoxi/.local/lib/python3.5/site-packages/django/template/defaulttags.py", line 507, in render
    current_app=current_app)
  File "/home/kudoxi/.local/lib/python3.5/site-packages/django/core/urlresolvers.py", line 600, in reverse
    return force_text(iri_to_uri(resolver._reverse_with_prefix(view, prefix, *args, **kwargs)))
  File "/home/kudoxi/.local/lib/python3.5/site-packages/django/core/urlresolvers.py", line 508, in _reverse_with_prefix
    (lookup_view_s, args, kwargs, len(patterns), patterns))
django.core.urlresolvers.NoReverseMatch: Reverse for 'StockProject./' with arguments '()' and keyword arguments '{}' not found. 0 pattern(s) tried: []

During handling of the above exception, another exception occurred:

Traceback (most recent call last):
  File "/home/kudoxi/.local/lib/python3.5/site-packages/django/core/handlers/base.py", line 149, in get_response
    response = self.process_exception_by_middleware(e, request)
  File "/home/kudoxi/.local/lib/python3.5/site-packages/django/core/handlers/base.py", line 147, in get_response
    response = wrapped_callback(request, *callback_args, **callback_kwargs)
  File "/home/kudoxi/PycharmProjects/StockWeb/index/views.py", line 15, in index
    return render(req,'index.html')
  File "/home/kudoxi/.local/lib/python3.5/site-packages/django/shortcuts.py", line 67, in render
    template_name, context, request=request, using=using)
  File "/home/kudoxi/.local/lib/python3.5/site-packages/django/template/loader.py", line 97, in render_to_string
    return template.render(context, request)
  File "/home/kudoxi/.local/lib/python3.5/site-packages/django/template/backends/django.py", line 95, in render
    return self.template.render(context)
  File "/home/kudoxi/.local/lib/python3.5/site-packages/django/template/base.py", line 206, in render
    return self._render(context)
  File "/home/kudoxi/.local/lib/python3.5/site-packages/django/template/base.py", line 197, in _render
    return self.nodelist.render(context)
  File "/home/kudoxi/.local/lib/python3.5/site-packages/django/template/base.py", line 988, in render
    bit = node.render_annotated(context)
  File "/home/kudoxi/.local/lib/python3.5/site-packages/django/template/base.py", line 955, in render_annotated
    return self.render(context)
  File "/home/kudoxi/.local/lib/python3.5/site-packages/django/template/loader_tags.py", line 173, in render
    return compiled_parent._render(context)
  File "/home/kudoxi/.local/lib/python3.5/site-packages/django/template/base.py", line 197, in _render
    return self.nodelist.render(context)
  File "/home/kudoxi/.local/lib/python3.5/site-packages/django/template/base.py", line 988, in render
    bit = node.render_annotated(context)
  File "/home/kudoxi/.local/lib/python3.5/site-packages/django/template/base.py", line 955, in render_annotated
    return self.render(context)
  File "/home/kudoxi/.local/lib/python3.5/site-packages/django/template/loader_tags.py", line 69, in render
    result = block.nodelist.render(context)
  File "/home/kudoxi/.local/lib/python3.5/site-packages/django/template/base.py", line 988, in render
    bit = node.render_annotated(context)
  File "/home/kudoxi/.local/lib/python3.5/site-packages/django/template/base.py", line 955, in render_annotated
    return self.render(context)
  File "/home/kudoxi/.local/lib/python3.5/site-packages/django/template/defaulttags.py", line 513, in render
    six.reraise(*exc_info)
  File "/home/kudoxi/.local/lib/python3.5/site-packages/django/utils/six.py", line 686, in reraise
    raise value
  File "/home/kudoxi/.local/lib/python3.5/site-packages/django/template/defaulttags.py", line 499, in render
    url = reverse(view_name, args=args, kwargs=kwargs, current_app=current_app)
  File "/home/kudoxi/.local/lib/python3.5/site-packages/django/core/urlresolvers.py", line 600, in reverse
    return force_text(iri_to_uri(resolver._reverse_with_prefix(view, prefix, *args, **kwargs)))
  File "/home/kudoxi/.local/lib/python3.5/site-packages/django/core/urlresolvers.py", line 508, in _reverse_with_prefix
    (lookup_view_s, args, kwargs, len(patterns), patterns))
django.core.urlresolvers.NoReverseMatch: Reverse for '/' with arguments '()' and keyword arguments '{}' not found. 0 pattern(s) tried: []
[2019-05-02 16:39:03,446][Thread-11:139654452430592][task_id:django.request][base.py:284][ERROR][Internal Server Error: /]
Traceback (most recent call last):
  File "/home/kudoxi/.local/lib/python3.5/site-packages/django/template/defaulttags.py", line 507, in render
    current_app=current_app)
  File "/home/kudoxi/.local/lib/python3.5/site-packages/django/core/urlresolvers.py", line 600, in reverse
    return force_text(iri_to_uri(resolver._reverse_with_prefix(view, prefix, *args, **kwargs)))
  File "/home/kudoxi/.local/lib/python3.5/site-packages/django/core/urlresolvers.py", line 508, in _reverse_with_prefix
    (lookup_view_s, args, kwargs, len(patterns), patterns))
django.core.urlresolvers.NoReverseMatch: Reverse for 'StockProject./' with arguments '()' and keyword arguments '{}' not found. 0 pattern(s) tried: []

During handling of the above exception, another exception occurred:

Traceback (most recent call last):
  File "/home/kudoxi/.local/lib/python3.5/site-packages/django/core/handlers/base.py", line 149, in get_response
    response = self.process_exception_by_middleware(e, request)
  File "/home/kudoxi/.local/lib/python3.5/site-packages/django/core/handlers/base.py", line 147, in get_response
    response = wrapped_callback(request, *callback_args, **callback_kwargs)
  File "/home/kudoxi/PycharmProjects/StockWeb/index/views.py", line 15, in index
    return render(req,'index.html')
  File "/home/kudoxi/.local/lib/python3.5/site-packages/django/shortcuts.py", line 67, in render
    template_name, context, request=request, using=using)
  File "/home/kudoxi/.local/lib/python3.5/site-packages/django/template/loader.py", line 97, in render_to_string
    return template.render(context, request)
  File "/home/kudoxi/.local/lib/python3.5/site-packages/django/template/backends/django.py", line 95, in render
    return self.template.render(context)
  File "/home/kudoxi/.local/lib/python3.5/site-packages/django/template/base.py", line 206, in render
    return self._render(context)
  File "/home/kudoxi/.local/lib/python3.5/site-packages/django/template/base.py", line 197, in _render
    return self.nodelist.render(context)
  File "/home/kudoxi/.local/lib/python3.5/site-packages/django/template/base.py", line 988, in render
    bit = node.render_annotated(context)
  File "/home/kudoxi/.local/lib/python3.5/site-packages/django/template/base.py", line 955, in render_annotated
    return self.render(context)
  File "/home/kudoxi/.local/lib/python3.5/site-packages/django/template/loader_tags.py", line 173, in render
    return compiled_parent._render(context)
  File "/home/kudoxi/.local/lib/python3.5/site-packages/django/template/base.py", line 197, in _render
    return self.nodelist.render(context)
  File "/home/kudoxi/.local/lib/python3.5/site-packages/django/template/base.py", line 988, in render
    bit = node.render_annotated(context)
  File "/home/kudoxi/.local/lib/python3.5/site-packages/django/template/base.py", line 955, in render_annotated
    return self.render(context)
  File "/home/kudoxi/.local/lib/python3.5/site-packages/django/template/loader_tags.py", line 69, in render
    result = block.nodelist.render(context)
  File "/home/kudoxi/.local/lib/python3.5/site-packages/django/template/base.py", line 988, in render
    bit = node.render_annotated(context)
  File "/home/kudoxi/.local/lib/python3.5/site-packages/django/template/base.py", line 955, in render_annotated
    return self.render(context)
  File "/home/kudoxi/.local/lib/python3.5/site-packages/django/template/defaulttags.py", line 513, in render
    six.reraise(*exc_info)
  File "/home/kudoxi/.local/lib/python3.5/site-packages/django/utils/six.py", line 686, in reraise
    raise value
  File "/home/kudoxi/.local/lib/python3.5/site-packages/django/template/defaulttags.py", line 499, in render
    url = reverse(view_name, args=args, kwargs=kwargs, current_app=current_app)
  File "/home/kudoxi/.local/lib/python3.5/site-packages/django/core/urlresolvers.py", line 600, in reverse
    return force_text(iri_to_uri(resolver._reverse_with_prefix(view, prefix, *args, **kwargs)))
  File "/home/kudoxi/.local/lib/python3.5/site-packages/django/core/urlresolvers.py", line 508, in _reverse_with_prefix
    (lookup_view_s, args, kwargs, len(patterns), patterns))
django.core.urlresolvers.NoReverseMatch: Reverse for '/' with arguments '()' and keyword arguments '{}' not found. 0 pattern(s) tried: []
[2019-05-02 16:52:05,799][Thread-7:139982012405504][task_id:django.request][base.py:284][ERROR][Internal Server Error: /stock_basics/]
Traceback (most recent call last):
  File "/home/kudoxi/.local/lib/python3.5/site-packages/django/core/handlers/base.py", line 149, in get_response
    response = self.process_exception_by_middleware(e, request)
  File "/home/kudoxi/.local/lib/python3.5/site-packages/django/core/handlers/base.py", line 147, in get_response
    response = wrapped_callback(request, *callback_args, **callback_kwargs)
  File "/home/kudoxi/PycharmProjects/StockWeb/index/views.py", line 35, in stock_basics
    if len(df) > 0:
TypeError: object of type 'NoneType' has no len()
[2019-05-04 08:48:05,011][Thread-3:139806987798272][task_id:django.request][base.py:284][ERROR][Internal Server Error: /stock_basics/]
Traceback (most recent call last):
  File "/home/kudoxi/.local/lib/python3.5/site-packages/django/core/handlers/base.py", line 149, in get_response
    response = self.process_exception_by_middleware(e, request)
  File "/home/kudoxi/.local/lib/python3.5/site-packages/django/core/handlers/base.py", line 147, in get_response
    response = wrapped_callback(request, *callback_args, **callback_kwargs)
  File "/home/kudoxi/PycharmProjects/StockWeb/index/views.py", line 40, in stock_basics
    params['date'] = df[1:,0]
  File "/home/kudoxi/.local/lib/python3.5/site-packages/pandas/core/frame.py", line 2927, in __getitem__
    indexer = self.columns.get_loc(key)
  File "/home/kudoxi/.local/lib/python3.5/site-packages/pandas/core/indexes/base.py", line 2657, in get_loc
    return self._engine.get_loc(key)
  File "pandas/_libs/index.pyx", line 108, in pandas._libs.index.IndexEngine.get_loc
  File "pandas/_libs/index.pyx", line 110, in pandas._libs.index.IndexEngine.get_loc
TypeError: '(slice(1, None, None), 0)' is an invalid key
[2019-05-04 08:49:57,152][Thread-3:140026528429824][task_id:django.request][base.py:284][ERROR][Internal Server Error: /stock_basics/]
Traceback (most recent call last):
  File "/home/kudoxi/.local/lib/python3.5/site-packages/pandas/core/indexes/base.py", line 2657, in get_loc
    return self._engine.get_loc(key)
  File "pandas/_libs/index.pyx", line 108, in pandas._libs.index.IndexEngine.get_loc
  File "pandas/_libs/index.pyx", line 132, in pandas._libs.index.IndexEngine.get_loc
  File "pandas/_libs/hashtable_class_helper.pxi", line 1601, in pandas._libs.hashtable.PyObjectHashTable.get_item
  File "pandas/_libs/hashtable_class_helper.pxi", line 1608, in pandas._libs.hashtable.PyObjectHashTable.get_item
KeyError: 'date'

During handling of the above exception, another exception occurred:

Traceback (most recent call last):
  File "/home/kudoxi/.local/lib/python3.5/site-packages/django/core/handlers/base.py", line 149, in get_response
    response = self.process_exception_by_middleware(e, request)
  File "/home/kudoxi/.local/lib/python3.5/site-packages/django/core/handlers/base.py", line 147, in get_response
    response = wrapped_callback(request, *callback_args, **callback_kwargs)
  File "/home/kudoxi/PycharmProjects/StockWeb/index/views.py", line 40, in stock_basics
    params['date'] = df['date']
  File "/home/kudoxi/.local/lib/python3.5/site-packages/pandas/core/frame.py", line 2927, in __getitem__
    indexer = self.columns.get_loc(key)
  File "/home/kudoxi/.local/lib/python3.5/site-packages/pandas/core/indexes/base.py", line 2659, in get_loc
    return self._engine.get_loc(self._maybe_cast_indexer(key))
  File "pandas/_libs/index.pyx", line 108, in pandas._libs.index.IndexEngine.get_loc
  File "pandas/_libs/index.pyx", line 132, in pandas._libs.index.IndexEngine.get_loc
  File "pandas/_libs/hashtable_class_helper.pxi", line 1601, in pandas._libs.hashtable.PyObjectHashTable.get_item
  File "pandas/_libs/hashtable_class_helper.pxi", line 1608, in pandas._libs.hashtable.PyObjectHashTable.get_item
KeyError: 'date'
[2019-05-04 08:52:57,984][Thread-3:140032390022912][task_id:django.request][base.py:284][ERROR][Internal Server Error: /stock_basics/]
Traceback (most recent call last):
  File "/home/kudoxi/.local/lib/python3.5/site-packages/django/core/handlers/base.py", line 149, in get_response
    response = self.process_exception_by_middleware(e, request)
  File "/home/kudoxi/.local/lib/python3.5/site-packages/django/core/handlers/base.py", line 147, in get_response
    response = wrapped_callback(request, *callback_args, **callback_kwargs)
  File "/home/kudoxi/PycharmProjects/StockWeb/index/views.py", line 40, in stock_basics
    params['date'] = df[1:,0]
  File "/home/kudoxi/.local/lib/python3.5/site-packages/pandas/core/frame.py", line 2927, in __getitem__
    indexer = self.columns.get_loc(key)
  File "/home/kudoxi/.local/lib/python3.5/site-packages/pandas/core/indexes/base.py", line 2657, in get_loc
    return self._engine.get_loc(key)
  File "pandas/_libs/index.pyx", line 108, in pandas._libs.index.IndexEngine.get_loc
  File "pandas/_libs/index.pyx", line 110, in pandas._libs.index.IndexEngine.get_loc
TypeError: '(slice(1, None, None), 0)' is an invalid key
[2019-05-04 08:54:02,664][Thread-3:139699226670848][task_id:django.request][base.py:284][ERROR][Internal Server Error: /stock_basics/]
Traceback (most recent call last):
  File "/home/kudoxi/.local/lib/python3.5/site-packages/django/core/handlers/base.py", line 149, in get_response
    response = self.process_exception_by_middleware(e, request)
  File "/home/kudoxi/.local/lib/python3.5/site-packages/django/core/handlers/base.py", line 147, in get_response
    response = wrapped_callback(request, *callback_args, **callback_kwargs)
  File "/home/kudoxi/PycharmProjects/StockWeb/index/views.py", line 41, in stock_basics
    params['date'] = data[1:,0]
  File "/home/kudoxi/.local/lib/python3.5/site-packages/pandas/core/frame.py", line 2927, in __getitem__
    indexer = self.columns.get_loc(key)
  File "/home/kudoxi/.local/lib/python3.5/site-packages/pandas/core/indexes/base.py", line 2657, in get_loc
    return self._engine.get_loc(key)
  File "pandas/_libs/index.pyx", line 108, in pandas._libs.index.IndexEngine.get_loc
  File "pandas/_libs/index.pyx", line 110, in pandas._libs.index.IndexEngine.get_loc
TypeError: '(slice(1, None, None), 0)' is an invalid key
[2019-05-04 08:54:22,943][Thread-6:139699226670848][task_id:django.request][base.py:284][ERROR][Internal Server Error: /stock_basics/]
Traceback (most recent call last):
  File "/home/kudoxi/.local/lib/python3.5/site-packages/django/core/handlers/base.py", line 149, in get_response
    response = self.process_exception_by_middleware(e, request)
  File "/home/kudoxi/.local/lib/python3.5/site-packages/django/core/handlers/base.py", line 147, in get_response
    response = wrapped_callback(request, *callback_args, **callback_kwargs)
  File "/home/kudoxi/PycharmProjects/StockWeb/index/views.py", line 41, in stock_basics
    params['date'] = data[1:,0]
  File "/home/kudoxi/.local/lib/python3.5/site-packages/pandas/core/frame.py", line 2927, in __getitem__
    indexer = self.columns.get_loc(key)
  File "/home/kudoxi/.local/lib/python3.5/site-packages/pandas/core/indexes/base.py", line 2657, in get_loc
    return self._engine.get_loc(key)
  File "pandas/_libs/index.pyx", line 108, in pandas._libs.index.IndexEngine.get_loc
  File "pandas/_libs/index.pyx", line 110, in pandas._libs.index.IndexEngine.get_loc
TypeError: '(slice(1, None, None), 0)' is an invalid key
[2019-05-04 08:56:08,270][Thread-3:140186822956800][task_id:django.request][base.py:284][ERROR][Internal Server Error: /stock_basics/]
Traceback (most recent call last):
  File "/home/kudoxi/.local/lib/python3.5/site-packages/django/core/handlers/base.py", line 149, in get_response
    response = self.process_exception_by_middleware(e, request)
  File "/home/kudoxi/.local/lib/python3.5/site-packages/django/core/handlers/base.py", line 147, in get_response
    response = wrapped_callback(request, *callback_args, **callback_kwargs)
  File "/home/kudoxi/PycharmProjects/StockWeb/index/views.py", line 44, in stock_basics
    return HttpResponse(json.dumps(params,ensure_ascii=False))
  File "/usr/lib/python3.5/json/__init__.py", line 237, in dumps
    **kw).encode(obj)
  File "/usr/lib/python3.5/json/encoder.py", line 198, in encode
    chunks = self.iterencode(o, _one_shot=True)
  File "/usr/lib/python3.5/json/encoder.py", line 256, in iterencode
    return _iterencode(o, 0)
  File "/usr/lib/python3.5/json/encoder.py", line 179, in default
    raise TypeError(repr(o) + " is not JSON serializable")
TypeError: array([33.7 , 34.08, 35.23, 37.5 , 36.14, 35.3 , 35.88, 35.52, 35.96,
       35.78, 34.7 , 33.05, 32.4 , 31.15, 31.91, 32.33, 36.3 , 30.98,
       30.25, 29.  , 27.88, 30.  , 31.3 , 30.37, 29.58, 29.37, 29.19,
       29.76, 30.  , 28.54, 30.5 , 29.  , 27.78, 26.  , 26.51, 25.62,
       26.  , 24.4 , 24.45, 23.72, 23.2 , 23.  , 23.15, 22.36, 21.72,
       21.91, 21.97, 22.36, 22.17, 21.41, 21.5 , 21.8 , 20.74, 20.5 ,
       19.98, 20.36, 20.22, 20.83, 20.54, 20.53, 20.65, 20.6 , 20.93,
       21.13, 21.26, 20.9 , 20.61, 20.38, 20.42, 20.25, 20.79, 20.98,
       21.26, 20.65, 19.7 , 20.75, 20.37, 20.61, 21.7 , 21.22, 21.35,
       21.92, 22.1 , 20.98, 20.91, 21.38, 20.66, 21.09, 20.82, 20.66,
       20.38, 19.9 , 20.86, 21.2 , 21.2 , 21.09, 20.99, 20.45, 20.93,
       22.2 , 22.8 , 23.06, 23.7 , 23.46, 22.7 , 22.  , 23.4 , 21.46,
       20.76, 20.1 , 19.89, 20.12, 20.32, 20.58, 21.7 , 19.35, 18.3 ,
       17.7 , 17.83, 17.13, 17.25, 17.02, 17.65, 16.54, 16.67, 16.94,
       16.18, 14.76, 16.1 , 17.  , 17.9 , 17.83, 16.15, 18.21, 19.5 ,
       21.76, 22.  , 21.94, 22.01, 22.16, 22.88, 23.1 , 21.73, 21.82,
       22.12, 21.88, 22.48, 23.04, 23.32, 24.21, 23.46, 23.63, 23.82,
       23.99, 23.5 , 24.01, 24.5 , 25.49, 23.59, 23.91, 23.7 , 23.72,
       23.6 , 23.5 , 23.75, 23.15, 23.99, 23.62, 24.  , 23.74, 23.29,
       23.65, 24.2 , 24.05, 24.61, 24.72, 25.63, 26.37, 26.2 , 26.56,
       27.2 , 26.05, 25.83, 24.7 , 24.55, 24.93, 24.68, 24.25, 24.33,
       23.29, 25.2 , 25.81, 26.45, 26.51, 25.01, 25.99, 23.9 , 25.9 ,
       24.  , 23.87, 23.91, 23.82, 24.06, 24.2 , 24.48, 23.9 , 23.69,
       24.31, 23.53, 22.8 , 22.88, 22.25, 21.49, 21.4 , 20.7 , 21.2 ,
       21.79, 22.69, 22.8 , 22.45, 22.4 , 23.71, 23.85, 23.71, 24.4 ,
       24.27, 24.99, 25.49, 25.15, 25.14, 24.6 , 24.4 , 24.42, 23.4 ,
       24.01, 23.7 , 23.67, 24.1 , 24.6 , 24.12, 24.  , 22.79, 22.42,
       22.3 , 22.34, 22.23, 22.25, 21.73, 22.81, 23.21, 23.39, 23.61,
       23.23, 23.  , 23.4 , 23.65, 23.99, 22.61, 22.61, 22.4 , 21.98,
       21.66, 22.91, 23.91, 24.04, 24.37, 24.66, 24.01, 24.4 , 24.1 ,
       25.3 , 25.21, 24.6 , 25.55, 28.  , 28.1 , 29.3 , 28.  , 28.61,
       28.78, 28.88, 28.8 , 28.6 , 28.67, 28.86, 31.8 , 33.85, 32.62,
       32.56, 31.45, 29.3 , 27.86, 28.2 , 29.  , 29.2 , 25.61, 25.63,
       25.3 , 26.4 , 26.26, 26.28, 27.26, 27.12, 27.8 , 27.49, 27.58,
       26.52, 24.87, 25.78, 27.  , 26.03, 25.66, 25.95, 26.66, 26.58,
       26.7 , 27.2 , 27.18, 26.9 , 25.5 , 24.41, 23.51, 23.76, 24.45,
       25.33, 24.16, 23.25, 23.45, 23.45, 22.5 , 22.87, 23.9 , 22.55,
       22.6 , 21.75, 21.8 , 21.37, 21.52, 21.1 , 21.85, 21.45, 21.62,
       21.62, 21.6 , 22.1 , 22.18, 22.13, 22.65, 22.78, 22.6 , 23.39,
       23.53, 23.07, 22.8 , 22.75, 22.52, 21.14, 20.63, 22.64, 23.28,
       23.6 , 22.26, 22.99, 21.11, 20.8 , 20.86, 20.59, 21.97, 21.59,
       21.6 , 21.78, 22.2 , 23.1 , 23.3 , 24.  , 23.32, 23.  , 23.75,
       21.  , 20.41, 19.33, 19.31, 18.25, 18.8 , 19.2 , 19.35, 18.59,
       18.74, 18.16, 18.15, 17.9 , 17.85, 17.1 , 16.95, 17.2 , 17.75,
       17.85, 17.81, 17.8 , 17.87, 17.5 , 17.3 , 17.85, 18.35, 18.63,
       18.53, 18.58, 19.1 , 19.31, 19.28, 19.2 , 18.87, 18.9 , 18.85,
       18.88, 19.58, 19.49, 20.07, 21.3 , 20.61, 20.67, 21.21, 21.3 ,
       20.26, 20.36, 21.3 , 20.81, 21.  , 19.73, 19.9 , 19.68, 19.8 ,
       19.78, 19.91, 19.5 , 19.88, 20.19, 20.47, 20.4 , 20.6 , 20.6 ,
       20.8 , 20.52, 20.92, 20.96, 21.17, 21.3 , 21.88, 22.13, 21.79,
       22.  , 21.61, 21.52, 21.82, 22.08, 20.99, 21.35, 21.7 , 21.46,
       22.17, 21.57, 21.5 , 20.75, 20.38, 20.72, 20.52, 20.55, 19.97,
       19.35, 19.13, 19.3 , 19.15, 19.29, 19.11, 18.63, 18.67, 18.65,
       18.51, 19.95, 20.26, 20.05, 20.31, 20.22, 20.38, 20.  , 19.78,
       19.44, 19.4 , 19.6 , 19.38, 19.59, 19.68, 19.81, 20.46, 18.5 ,
       18.49, 18.45, 18.5 , 18.53, 17.98, 18.11, 19.04, 19.48, 20.91,
       21.3 , 21.14, 21.18, 20.85, 21.58, 21.5 , 22.21, 25.  , 24.5 ,
       24.36, 25.22, 24.9 , 24.48, 24.4 , 23.17, 23.11, 23.17, 23.16,
       23.8 , 24.1 , 23.78]) is not JSON serializable
[2019-05-04 08:56:50,716][Thread-3:139770666764032][task_id:django.request][base.py:284][ERROR][Internal Server Error: /stock_basics/]
Traceback (most recent call last):
  File "/home/kudoxi/.local/lib/python3.5/site-packages/django/core/handlers/base.py", line 149, in get_response
    response = self.process_exception_by_middleware(e, request)
  File "/home/kudoxi/.local/lib/python3.5/site-packages/django/core/handlers/base.py", line 147, in get_response
    response = wrapped_callback(request, *callback_args, **callback_kwargs)
  File "/home/kudoxi/PycharmProjects/StockWeb/index/views.py", line 44, in stock_basics
    return HttpResponse(json.dumps(params,ensure_ascii=False))
  File "/usr/lib/python3.5/json/__init__.py", line 237, in dumps
    **kw).encode(obj)
  File "/usr/lib/python3.5/json/encoder.py", line 198, in encode
    chunks = self.iterencode(o, _one_shot=True)
  File "/usr/lib/python3.5/json/encoder.py", line 256, in iterencode
    return _iterencode(o, 0)
  File "/usr/lib/python3.5/json/encoder.py", line 179, in default
    raise TypeError(repr(o) + " is not JSON serializable")
TypeError: array([33.7 , 34.08, 35.23, 37.5 , 36.14, 35.3 , 35.88, 35.52, 35.96,
       35.78, 34.7 , 33.05, 32.4 , 31.15, 31.91, 32.33, 36.3 , 30.98,
       30.25, 29.  , 27.88, 30.  , 31.3 , 30.37, 29.58, 29.37, 29.19,
       29.76, 30.  , 28.54, 30.5 , 29.  , 27.78, 26.  , 26.51, 25.62,
       26.  , 24.4 , 24.45, 23.72, 23.2 , 23.  , 23.15, 22.36, 21.72,
       21.91, 21.97, 22.36, 22.17, 21.41, 21.5 , 21.8 , 20.74, 20.5 ,
       19.98, 20.36, 20.22, 20.83, 20.54, 20.53, 20.65, 20.6 , 20.93,
       21.13, 21.26, 20.9 , 20.61, 20.38, 20.42, 20.25, 20.79, 20.98,
       21.26, 20.65, 19.7 , 20.75, 20.37, 20.61, 21.7 , 21.22, 21.35,
       21.92, 22.1 , 20.98, 20.91, 21.38, 20.66, 21.09, 20.82, 20.66,
       20.38, 19.9 , 20.86, 21.2 , 21.2 , 21.09, 20.99, 20.45, 20.93,
       22.2 , 22.8 , 23.06, 23.7 , 23.46, 22.7 , 22.  , 23.4 , 21.46,
       20.76, 20.1 , 19.89, 20.12, 20.32, 20.58, 21.7 , 19.35, 18.3 ,
       17.7 , 17.83, 17.13, 17.25, 17.02, 17.65, 16.54, 16.67, 16.94,
       16.18, 14.76, 16.1 , 17.  , 17.9 , 17.83, 16.15, 18.21, 19.5 ,
       21.76, 22.  , 21.94, 22.01, 22.16, 22.88, 23.1 , 21.73, 21.82,
       22.12, 21.88, 22.48, 23.04, 23.32, 24.21, 23.46, 23.63, 23.82,
       23.99, 23.5 , 24.01, 24.5 , 25.49, 23.59, 23.91, 23.7 , 23.72,
       23.6 , 23.5 , 23.75, 23.15, 23.99, 23.62, 24.  , 23.74, 23.29,
       23.65, 24.2 , 24.05, 24.61, 24.72, 25.63, 26.37, 26.2 , 26.56,
       27.2 , 26.05, 25.83, 24.7 , 24.55, 24.93, 24.68, 24.25, 24.33,
       23.29, 25.2 , 25.81, 26.45, 26.51, 25.01, 25.99, 23.9 , 25.9 ,
       24.  , 23.87, 23.91, 23.82, 24.06, 24.2 , 24.48, 23.9 , 23.69,
       24.31, 23.53, 22.8 , 22.88, 22.25, 21.49, 21.4 , 20.7 , 21.2 ,
       21.79, 22.69, 22.8 , 22.45, 22.4 , 23.71, 23.85, 23.71, 24.4 ,
       24.27, 24.99, 25.49, 25.15, 25.14, 24.6 , 24.4 , 24.42, 23.4 ,
       24.01, 23.7 , 23.67, 24.1 , 24.6 , 24.12, 24.  , 22.79, 22.42,
       22.3 , 22.34, 22.23, 22.25, 21.73, 22.81, 23.21, 23.39, 23.61,
       23.23, 23.  , 23.4 , 23.65, 23.99, 22.61, 22.61, 22.4 , 21.98,
       21.66, 22.91, 23.91, 24.04, 24.37, 24.66, 24.01, 24.4 , 24.1 ,
       25.3 , 25.21, 24.6 , 25.55, 28.  , 28.1 , 29.3 , 28.  , 28.61,
       28.78, 28.88, 28.8 , 28.6 , 28.67, 28.86, 31.8 , 33.85, 32.62,
       32.56, 31.45, 29.3 , 27.86, 28.2 , 29.  , 29.2 , 25.61, 25.63,
       25.3 , 26.4 , 26.26, 26.28, 27.26, 27.12, 27.8 , 27.49, 27.58,
       26.52, 24.87, 25.78, 27.  , 26.03, 25.66, 25.95, 26.66, 26.58,
       26.7 , 27.2 , 27.18, 26.9 , 25.5 , 24.41, 23.51, 23.76, 24.45,
       25.33, 24.16, 23.25, 23.45, 23.45, 22.5 , 22.87, 23.9 , 22.55,
       22.6 , 21.75, 21.8 , 21.37, 21.52, 21.1 , 21.85, 21.45, 21.62,
       21.62, 21.6 , 22.1 , 22.18, 22.13, 22.65, 22.78, 22.6 , 23.39,
       23.53, 23.07, 22.8 , 22.75, 22.52, 21.14, 20.63, 22.64, 23.28,
       23.6 , 22.26, 22.99, 21.11, 20.8 , 20.86, 20.59, 21.97, 21.59,
       21.6 , 21.78, 22.2 , 23.1 , 23.3 , 24.  , 23.32, 23.  , 23.75,
       21.  , 20.41, 19.33, 19.31, 18.25, 18.8 , 19.2 , 19.35, 18.59,
       18.74, 18.16, 18.15, 17.9 , 17.85, 17.1 , 16.95, 17.2 , 17.75,
       17.85, 17.81, 17.8 , 17.87, 17.5 , 17.3 , 17.85, 18.35, 18.63,
       18.53, 18.58, 19.1 , 19.31, 19.28, 19.2 , 18.87, 18.9 , 18.85,
       18.88, 19.58, 19.49, 20.07, 21.3 , 20.61, 20.67, 21.21, 21.3 ,
       20.26, 20.36, 21.3 , 20.81, 21.  , 19.73, 19.9 , 19.68, 19.8 ,
       19.78, 19.91, 19.5 , 19.88, 20.19, 20.47, 20.4 , 20.6 , 20.6 ,
       20.8 , 20.52, 20.92, 20.96, 21.17, 21.3 , 21.88, 22.13, 21.79,
       22.  , 21.61, 21.52, 21.82, 22.08, 20.99, 21.35, 21.7 , 21.46,
       22.17, 21.57, 21.5 , 20.75, 20.38, 20.72, 20.52, 20.55, 19.97,
       19.35, 19.13, 19.3 , 19.15, 19.29, 19.11, 18.63, 18.67, 18.65,
       18.51, 19.95, 20.26, 20.05, 20.31, 20.22, 20.38, 20.  , 19.78,
       19.44, 19.4 , 19.6 , 19.38, 19.59, 19.68, 19.81, 20.46, 18.5 ,
       18.49, 18.45, 18.5 , 18.53, 17.98, 18.11, 19.04, 19.48, 20.91,
       21.3 , 21.14, 21.18, 20.85, 21.58, 21.5 , 22.21, 25.  , 24.5 ,
       24.36, 25.22, 24.9 , 24.48, 24.4 , 23.17, 23.11, 23.17, 23.16,
       23.8 , 24.1 , 23.78]) is not JSON serializable
[2019-05-04 08:57:09,560][Thread-6:139770666764032][task_id:django.request][base.py:284][ERROR][Internal Server Error: /stock_basics/]
Traceback (most recent call last):
  File "/home/kudoxi/.local/lib/python3.5/site-packages/django/core/handlers/base.py", line 149, in get_response
    response = self.process_exception_by_middleware(e, request)
  File "/home/kudoxi/.local/lib/python3.5/site-packages/django/core/handlers/base.py", line 147, in get_response
    response = wrapped_callback(request, *callback_args, **callback_kwargs)
  File "/home/kudoxi/PycharmProjects/StockWeb/index/views.py", line 44, in stock_basics
    return HttpResponse(json.dumps(params,ensure_ascii=False))
  File "/usr/lib/python3.5/json/__init__.py", line 237, in dumps
    **kw).encode(obj)
  File "/usr/lib/python3.5/json/encoder.py", line 198, in encode
    chunks = self.iterencode(o, _one_shot=True)
  File "/usr/lib/python3.5/json/encoder.py", line 256, in iterencode
    return _iterencode(o, 0)
  File "/usr/lib/python3.5/json/encoder.py", line 179, in default
    raise TypeError(repr(o) + " is not JSON serializable")
TypeError: array([33.7 , 34.08, 35.23, 37.5 , 36.14, 35.3 , 35.88, 35.52, 35.96,
       35.78, 34.7 , 33.05, 32.4 , 31.15, 31.91, 32.33, 36.3 , 30.98,
       30.25, 29.  , 27.88, 30.  , 31.3 , 30.37, 29.58, 29.37, 29.19,
       29.76, 30.  , 28.54, 30.5 , 29.  , 27.78, 26.  , 26.51, 25.62,
       26.  , 24.4 , 24.45, 23.72, 23.2 , 23.  , 23.15, 22.36, 21.72,
       21.91, 21.97, 22.36, 22.17, 21.41, 21.5 , 21.8 , 20.74, 20.5 ,
       19.98, 20.36, 20.22, 20.83, 20.54, 20.53, 20.65, 20.6 , 20.93,
       21.13, 21.26, 20.9 , 20.61, 20.38, 20.42, 20.25, 20.79, 20.98,
       21.26, 20.65, 19.7 , 20.75, 20.37, 20.61, 21.7 , 21.22, 21.35,
       21.92, 22.1 , 20.98, 20.91, 21.38, 20.66, 21.09, 20.82, 20.66,
       20.38, 19.9 , 20.86, 21.2 , 21.2 , 21.09, 20.99, 20.45, 20.93,
       22.2 , 22.8 , 23.06, 23.7 , 23.46, 22.7 , 22.  , 23.4 , 21.46,
       20.76, 20.1 , 19.89, 20.12, 20.32, 20.58, 21.7 , 19.35, 18.3 ,
       17.7 , 17.83, 17.13, 17.25, 17.02, 17.65, 16.54, 16.67, 16.94,
       16.18, 14.76, 16.1 , 17.  , 17.9 , 17.83, 16.15, 18.21, 19.5 ,
       21.76, 22.  , 21.94, 22.01, 22.16, 22.88, 23.1 , 21.73, 21.82,
       22.12, 21.88, 22.48, 23.04, 23.32, 24.21, 23.46, 23.63, 23.82,
       23.99, 23.5 , 24.01, 24.5 , 25.49, 23.59, 23.91, 23.7 , 23.72,
       23.6 , 23.5 , 23.75, 23.15, 23.99, 23.62, 24.  , 23.74, 23.29,
       23.65, 24.2 , 24.05, 24.61, 24.72, 25.63, 26.37, 26.2 , 26.56,
       27.2 , 26.05, 25.83, 24.7 , 24.55, 24.93, 24.68, 24.25, 24.33,
       23.29, 25.2 , 25.81, 26.45, 26.51, 25.01, 25.99, 23.9 , 25.9 ,
       24.  , 23.87, 23.91, 23.82, 24.06, 24.2 , 24.48, 23.9 , 23.69,
       24.31, 23.53, 22.8 , 22.88, 22.25, 21.49, 21.4 , 20.7 , 21.2 ,
       21.79, 22.69, 22.8 , 22.45, 22.4 , 23.71, 23.85, 23.71, 24.4 ,
       24.27, 24.99, 25.49, 25.15, 25.14, 24.6 , 24.4 , 24.42, 23.4 ,
       24.01, 23.7 , 23.67, 24.1 , 24.6 , 24.12, 24.  , 22.79, 22.42,
       22.3 , 22.34, 22.23, 22.25, 21.73, 22.81, 23.21, 23.39, 23.61,
       23.23, 23.  , 23.4 , 23.65, 23.99, 22.61, 22.61, 22.4 , 21.98,
       21.66, 22.91, 23.91, 24.04, 24.37, 24.66, 24.01, 24.4 , 24.1 ,
       25.3 , 25.21, 24.6 , 25.55, 28.  , 28.1 , 29.3 , 28.  , 28.61,
       28.78, 28.88, 28.8 , 28.6 , 28.67, 28.86, 31.8 , 33.85, 32.62,
       32.56, 31.45, 29.3 , 27.86, 28.2 , 29.  , 29.2 , 25.61, 25.63,
       25.3 , 26.4 , 26.26, 26.28, 27.26, 27.12, 27.8 , 27.49, 27.58,
       26.52, 24.87, 25.78, 27.  , 26.03, 25.66, 25.95, 26.66, 26.58,
       26.7 , 27.2 , 27.18, 26.9 , 25.5 , 24.41, 23.51, 23.76, 24.45,
       25.33, 24.16, 23.25, 23.45, 23.45, 22.5 , 22.87, 23.9 , 22.55,
       22.6 , 21.75, 21.8 , 21.37, 21.52, 21.1 , 21.85, 21.45, 21.62,
       21.62, 21.6 , 22.1 , 22.18, 22.13, 22.65, 22.78, 22.6 , 23.39,
       23.53, 23.07, 22.8 , 22.75, 22.52, 21.14, 20.63, 22.64, 23.28,
       23.6 , 22.26, 22.99, 21.11, 20.8 , 20.86, 20.59, 21.97, 21.59,
       21.6 , 21.78, 22.2 , 23.1 , 23.3 , 24.  , 23.32, 23.  , 23.75,
       21.  , 20.41, 19.33, 19.31, 18.25, 18.8 , 19.2 , 19.35, 18.59,
       18.74, 18.16, 18.15, 17.9 , 17.85, 17.1 , 16.95, 17.2 , 17.75,
       17.85, 17.81, 17.8 , 17.87, 17.5 , 17.3 , 17.85, 18.35, 18.63,
       18.53, 18.58, 19.1 , 19.31, 19.28, 19.2 , 18.87, 18.9 , 18.85,
       18.88, 19.58, 19.49, 20.07, 21.3 , 20.61, 20.67, 21.21, 21.3 ,
       20.26, 20.36, 21.3 , 20.81, 21.  , 19.73, 19.9 , 19.68, 19.8 ,
       19.78, 19.91, 19.5 , 19.88, 20.19, 20.47, 20.4 , 20.6 , 20.6 ,
       20.8 , 20.52, 20.92, 20.96, 21.17, 21.3 , 21.88, 22.13, 21.79,
       22.  , 21.61, 21.52, 21.82, 22.08, 20.99, 21.35, 21.7 , 21.46,
       22.17, 21.57, 21.5 , 20.75, 20.38, 20.72, 20.52, 20.55, 19.97,
       19.35, 19.13, 19.3 , 19.15, 19.29, 19.11, 18.63, 18.67, 18.65,
       18.51, 19.95, 20.26, 20.05, 20.31, 20.22, 20.38, 20.  , 19.78,
       19.44, 19.4 , 19.6 , 19.38, 19.59, 19.68, 19.81, 20.46, 18.5 ,
       18.49, 18.45, 18.5 , 18.53, 17.98, 18.11, 19.04, 19.48, 20.91,
       21.3 , 21.14, 21.18, 20.85, 21.58, 21.5 , 22.21, 25.  , 24.5 ,
       24.36, 25.22, 24.9 , 24.48, 24.4 , 23.17, 23.11, 23.17, 23.16,
       23.8 , 24.1 , 23.78]) is not JSON serializable
[2019-05-04 08:58:39,021][Thread-3:140056327362304][task_id:django.request][base.py:284][ERROR][Internal Server Error: /stock_basics/]
Traceback (most recent call last):
  File "/home/kudoxi/.local/lib/python3.5/site-packages/django/core/handlers/base.py", line 149, in get_response
    response = self.process_exception_by_middleware(e, request)
  File "/home/kudoxi/.local/lib/python3.5/site-packages/django/core/handlers/base.py", line 147, in get_response
    response = wrapped_callback(request, *callback_args, **callback_kwargs)
  File "/home/kudoxi/PycharmProjects/StockWeb/index/views.py", line 44, in stock_basics
    return HttpResponse(json.dumps(params,ensure_ascii=False))
  File "/usr/lib/python3.5/json/__init__.py", line 237, in dumps
    **kw).encode(obj)
  File "/usr/lib/python3.5/json/encoder.py", line 198, in encode
    chunks = self.iterencode(o, _one_shot=True)
  File "/usr/lib/python3.5/json/encoder.py", line 256, in iterencode
    return _iterencode(o, 0)
  File "/usr/lib/python3.5/json/encoder.py", line 179, in default
    raise TypeError(repr(o) + " is not JSON serializable")
TypeError: array([33.7 , 34.08, 35.23, 37.5 , 36.14, 35.3 , 35.88, 35.52, 35.96,
       35.78, 34.7 , 33.05, 32.4 , 31.15, 31.91, 32.33, 36.3 , 30.98,
       30.25, 29.  , 27.88, 30.  , 31.3 , 30.37, 29.58, 29.37, 29.19,
       29.76, 30.  , 28.54, 30.5 , 29.  , 27.78, 26.  , 26.51, 25.62,
       26.  , 24.4 , 24.45, 23.72, 23.2 , 23.  , 23.15, 22.36, 21.72,
       21.91, 21.97, 22.36, 22.17, 21.41, 21.5 , 21.8 , 20.74, 20.5 ,
       19.98, 20.36, 20.22, 20.83, 20.54, 20.53, 20.65, 20.6 , 20.93,
       21.13, 21.26, 20.9 , 20.61, 20.38, 20.42, 20.25, 20.79, 20.98,
       21.26, 20.65, 19.7 , 20.75, 20.37, 20.61, 21.7 , 21.22, 21.35,
       21.92, 22.1 , 20.98, 20.91, 21.38, 20.66, 21.09, 20.82, 20.66,
       20.38, 19.9 , 20.86, 21.2 , 21.2 , 21.09, 20.99, 20.45, 20.93,
       22.2 , 22.8 , 23.06, 23.7 , 23.46, 22.7 , 22.  , 23.4 , 21.46,
       20.76, 20.1 , 19.89, 20.12, 20.32, 20.58, 21.7 , 19.35, 18.3 ,
       17.7 , 17.83, 17.13, 17.25, 17.02, 17.65, 16.54, 16.67, 16.94,
       16.18, 14.76, 16.1 , 17.  , 17.9 , 17.83, 16.15, 18.21, 19.5 ,
       21.76, 22.  , 21.94, 22.01, 22.16, 22.88, 23.1 , 21.73, 21.82,
       22.12, 21.88, 22.48, 23.04, 23.32, 24.21, 23.46, 23.63, 23.82,
       23.99, 23.5 , 24.01, 24.5 , 25.49, 23.59, 23.91, 23.7 , 23.72,
       23.6 , 23.5 , 23.75, 23.15, 23.99, 23.62, 24.  , 23.74, 23.29,
       23.65, 24.2 , 24.05, 24.61, 24.72, 25.63, 26.37, 26.2 , 26.56,
       27.2 , 26.05, 25.83, 24.7 , 24.55, 24.93, 24.68, 24.25, 24.33,
       23.29, 25.2 , 25.81, 26.45, 26.51, 25.01, 25.99, 23.9 , 25.9 ,
       24.  , 23.87, 23.91, 23.82, 24.06, 24.2 , 24.48, 23.9 , 23.69,
       24.31, 23.53, 22.8 , 22.88, 22.25, 21.49, 21.4 , 20.7 , 21.2 ,
       21.79, 22.69, 22.8 , 22.45, 22.4 , 23.71, 23.85, 23.71, 24.4 ,
       24.27, 24.99, 25.49, 25.15, 25.14, 24.6 , 24.4 , 24.42, 23.4 ,
       24.01, 23.7 , 23.67, 24.1 , 24.6 , 24.12, 24.  , 22.79, 22.42,
       22.3 , 22.34, 22.23, 22.25, 21.73, 22.81, 23.21, 23.39, 23.61,
       23.23, 23.  , 23.4 , 23.65, 23.99, 22.61, 22.61, 22.4 , 21.98,
       21.66, 22.91, 23.91, 24.04, 24.37, 24.66, 24.01, 24.4 , 24.1 ,
       25.3 , 25.21, 24.6 , 25.55, 28.  , 28.1 , 29.3 , 28.  , 28.61,
       28.78, 28.88, 28.8 , 28.6 , 28.67, 28.86, 31.8 , 33.85, 32.62,
       32.56, 31.45, 29.3 , 27.86, 28.2 , 29.  , 29.2 , 25.61, 25.63,
       25.3 , 26.4 , 26.26, 26.28, 27.26, 27.12, 27.8 , 27.49, 27.58,
       26.52, 24.87, 25.78, 27.  , 26.03, 25.66, 25.95, 26.66, 26.58,
       26.7 , 27.2 , 27.18, 26.9 , 25.5 , 24.41, 23.51, 23.76, 24.45,
       25.33, 24.16, 23.25, 23.45, 23.45, 22.5 , 22.87, 23.9 , 22.55,
       22.6 , 21.75, 21.8 , 21.37, 21.52, 21.1 , 21.85, 21.45, 21.62,
       21.62, 21.6 , 22.1 , 22.18, 22.13, 22.65, 22.78, 22.6 , 23.39,
       23.53, 23.07, 22.8 , 22.75, 22.52, 21.14, 20.63, 22.64, 23.28,
       23.6 , 22.26, 22.99, 21.11, 20.8 , 20.86, 20.59, 21.97, 21.59,
       21.6 , 21.78, 22.2 , 23.1 , 23.3 , 24.  , 23.32, 23.  , 23.75,
       21.  , 20.41, 19.33, 19.31, 18.25, 18.8 , 19.2 , 19.35, 18.59,
       18.74, 18.16, 18.15, 17.9 , 17.85, 17.1 , 16.95, 17.2 , 17.75,
       17.85, 17.81, 17.8 , 17.87, 17.5 , 17.3 , 17.85, 18.35, 18.63,
       18.53, 18.58, 19.1 , 19.31, 19.28, 19.2 , 18.87, 18.9 , 18.85,
       18.88, 19.58, 19.49, 20.07, 21.3 , 20.61, 20.67, 21.21, 21.3 ,
       20.26, 20.36, 21.3 , 20.81, 21.  , 19.73, 19.9 , 19.68, 19.8 ,
       19.78, 19.91, 19.5 , 19.88, 20.19, 20.47, 20.4 , 20.6 , 20.6 ,
       20.8 , 20.52, 20.92, 20.96, 21.17, 21.3 , 21.88, 22.13, 21.79,
       22.  , 21.61, 21.52, 21.82, 22.08, 20.99, 21.35, 21.7 , 21.46,
       22.17, 21.57, 21.5 , 20.75, 20.38, 20.72, 20.52, 20.55, 19.97,
       19.35, 19.13, 19.3 , 19.15, 19.29, 19.11, 18.63, 18.67, 18.65,
       18.51, 19.95, 20.26, 20.05, 20.31, 20.22, 20.38, 20.  , 19.78,
       19.44, 19.4 , 19.6 , 19.38, 19.59, 19.68, 19.81, 20.46, 18.5 ,
       18.49, 18.45, 18.5 , 18.53, 17.98, 18.11, 19.04, 19.48, 20.91,
       21.3 , 21.14, 21.18, 20.85, 21.58, 21.5 , 22.21, 25.  , 24.5 ,
       24.36, 25.22, 24.9 , 24.48, 24.4 , 23.17, 23.11, 23.17, 23.16,
       23.8 , 24.1 , 23.78]) is not JSON serializable
[2019-05-04 09:01:00,784][Thread-3:140249493718784][task_id:django.request][base.py:284][ERROR][Internal Server Error: /stock_basics/]
Traceback (most recent call last):
  File "/home/kudoxi/.local/lib/python3.5/site-packages/django/core/handlers/base.py", line 149, in get_response
    response = self.process_exception_by_middleware(e, request)
  File "/home/kudoxi/.local/lib/python3.5/site-packages/django/core/handlers/base.py", line 147, in get_response
    response = wrapped_callback(request, *callback_args, **callback_kwargs)
  File "/home/kudoxi/PycharmProjects/StockWeb/index/views.py", line 43, in stock_basics
    return HttpResponse(json.dumps(params,ensure_ascii=False))
  File "/usr/lib/python3.5/json/__init__.py", line 237, in dumps
    **kw).encode(obj)
  File "/usr/lib/python3.5/json/encoder.py", line 198, in encode
    chunks = self.iterencode(o, _one_shot=True)
  File "/usr/lib/python3.5/json/encoder.py", line 256, in iterencode
    return _iterencode(o, 0)
  File "/usr/lib/python3.5/json/encoder.py", line 179, in default
    raise TypeError(repr(o) + " is not JSON serializable")
TypeError: date
2019-04-29    33.70
2019-04-26    34.08
2019-04-25    35.23
2019-04-24    37.50
2019-04-23    36.14
2019-04-22    35.30
2019-04-19    35.88
2019-04-18    35.52
2019-04-17    35.96
2019-04-16    35.78
2019-04-15    34.70
2019-04-12    33.05
2019-04-11    32.40
2019-04-10    31.15
2019-04-09    31.91
2019-04-08    32.33
2019-04-04    36.30
2019-04-03    30.98
2019-04-02    30.25
2019-04-01    29.00
2019-03-29    27.88
2019-03-28    30.00
2019-03-26    31.30
2019-03-25    30.37
2019-03-22    29.58
2019-03-21    29.37
2019-03-20    29.19
2019-03-19    29.76
2019-03-18    30.00
2019-03-15    28.54
              ...  
2016-12-21    18.49
2016-12-20    18.45
2016-12-19    18.50
2016-12-16    18.53
2016-12-15    17.98
2016-12-14    18.11
2016-12-13    19.04
2016-12-12    19.48
2016-12-09    20.91
2016-12-08    21.30
2016-12-07    21.14
2016-12-06    21.18
2016-12-05    20.85
2016-12-02    21.58
2016-12-01    21.50
2016-11-30    22.21
2016-11-29    25.00
2016-11-16    24.50
2016-11-15    24.36
2016-11-14    25.22
2016-11-11    24.90
2016-11-10    24.48
2016-11-09    24.40
2016-11-08    23.17
2016-11-07    23.11
2016-11-04    23.17
2016-11-03    23.16
2016-11-02    23.80
2016-11-01    24.10
2016-10-31    23.78
Name: open, Length: 525, dtype: float64 is not JSON serializable
[2019-05-04 09:11:49,481][Thread-3:139956766521088][task_id:django.request][base.py:284][ERROR][Internal Server Error: /stock_basics/]
Traceback (most recent call last):
  File "/home/kudoxi/.local/lib/python3.5/site-packages/django/core/handlers/base.py", line 149, in get_response
    response = self.process_exception_by_middleware(e, request)
  File "/home/kudoxi/.local/lib/python3.5/site-packages/django/core/handlers/base.py", line 147, in get_response
    response = wrapped_callback(request, *callback_args, **callback_kwargs)
  File "/home/kudoxi/PycharmProjects/StockWeb/index/views.py", line 42, in stock_basics
    dates = serializers.serialize("json",date)
  File "/home/kudoxi/.local/lib/python3.5/site-packages/django/core/serializers/__init__.py", line 129, in serialize
    s.serialize(queryset, **options)
  File "/home/kudoxi/.local/lib/python3.5/site-packages/django/core/serializers/base.py", line 83, in serialize
    concrete_model = obj._meta.concrete_model
AttributeError: 'float' object has no attribute '_meta'
[2019-05-04 09:14:58,963][Thread-3:140154573436672][task_id:django.request][base.py:284][ERROR][Internal Server Error: /stock_basics/]
Traceback (most recent call last):
  File "/home/kudoxi/.local/lib/python3.5/site-packages/django/core/handlers/base.py", line 149, in get_response
    response = self.process_exception_by_middleware(e, request)
  File "/home/kudoxi/.local/lib/python3.5/site-packages/django/core/handlers/base.py", line 147, in get_response
    response = wrapped_callback(request, *callback_args, **callback_kwargs)
  File "/home/kudoxi/PycharmProjects/StockWeb/index/views.py", line 42, in stock_basics
    pd.set_option('display.height', 1000)
  File "/home/kudoxi/.local/lib/python3.5/site-packages/pandas/core/config.py", line 227, in __call__
    return self.__func__(*args, **kwds)
  File "/home/kudoxi/.local/lib/python3.5/site-packages/pandas/core/config.py", line 119, in _set_option
    key = _get_single_key(k, silent)
  File "/home/kudoxi/.local/lib/python3.5/site-packages/pandas/core/config.py", line 83, in _get_single_key
    raise OptionError('No such keys(s): {pat!r}'.format(pat=pat))
pandas.core.config.OptionError: "No such keys(s): 'display.height'"
[2019-05-04 09:17:35,866][Thread-3:140631724783360][task_id:django.request][base.py:284][ERROR][Internal Server Error: /stock_basics/]
Traceback (most recent call last):
  File "/home/kudoxi/.local/lib/python3.5/site-packages/django/core/handlers/base.py", line 149, in get_response
    response = self.process_exception_by_middleware(e, request)
  File "/home/kudoxi/.local/lib/python3.5/site-packages/django/core/handlers/base.py", line 147, in get_response
    response = wrapped_callback(request, *callback_args, **callback_kwargs)
  File "/home/kudoxi/PycharmProjects/StockWeb/index/views.py", line 47, in stock_basics
    dates = serializers.serialize("json",date)
  File "/home/kudoxi/.local/lib/python3.5/site-packages/django/core/serializers/__init__.py", line 129, in serialize
    s.serialize(queryset, **options)
  File "/home/kudoxi/.local/lib/python3.5/site-packages/django/core/serializers/base.py", line 83, in serialize
    concrete_model = obj._meta.concrete_model
AttributeError: 'str' object has no attribute '_meta'
[2019-05-04 09:18:46,919][Thread-3:140380063143680][task_id:django.request][base.py:284][ERROR][Internal Server Error: /stock_basics/]
Traceback (most recent call last):
  File "/home/kudoxi/.local/lib/python3.5/site-packages/django/core/handlers/base.py", line 149, in get_response
    response = self.process_exception_by_middleware(e, request)
  File "/home/kudoxi/.local/lib/python3.5/site-packages/django/core/handlers/base.py", line 147, in get_response
    response = wrapped_callback(request, *callback_args, **callback_kwargs)
  File "/home/kudoxi/PycharmProjects/StockWeb/index/views.py", line 50, in stock_basics
    return HttpResponse(json.dumps(params,ensure_ascii=False))
  File "/usr/lib/python3.5/json/__init__.py", line 237, in dumps
    **kw).encode(obj)
  File "/usr/lib/python3.5/json/encoder.py", line 198, in encode
    chunks = self.iterencode(o, _one_shot=True)
  File "/usr/lib/python3.5/json/encoder.py", line 256, in iterencode
    return _iterencode(o, 0)
  File "/usr/lib/python3.5/json/encoder.py", line 179, in default
    raise TypeError(repr(o) + " is not JSON serializable")
TypeError: Index(['2019-04-30', '2019-04-29', '2019-04-26', '2019-04-25', '2019-04-24',
       '2019-04-23', '2019-04-22', '2019-04-19', '2019-04-18', '2019-04-17',
       ...
       '2016-11-11', '2016-11-10', '2016-11-09', '2016-11-08', '2016-11-07',
       '2016-11-04', '2016-11-03', '2016-11-02', '2016-11-01', '2016-10-31'],
      dtype='object', name='date', length=526) is not JSON serializable
[2019-05-04 09:25:13,590][Thread-4:140160514639616][task_id:django.request][base.py:284][ERROR][Internal Server Error: /stock_basics/]
Traceback (most recent call last):
  File "/home/kudoxi/.local/lib/python3.5/site-packages/django/core/handlers/base.py", line 149, in get_response
    response = self.process_exception_by_middleware(e, request)
  File "/home/kudoxi/.local/lib/python3.5/site-packages/django/core/handlers/base.py", line 147, in get_response
    response = wrapped_callback(request, *callback_args, **callback_kwargs)
  File "/home/kudoxi/PycharmProjects/StockWeb/index/views.py", line 53, in stock_basics
    lines = json.dumps(dict(date), cls=DateEnconding)
ValueError: dictionary update sequence element #0 has length 10; 2 is required
[2019-05-04 09:28:42,457][Thread-3:140275843471104][task_id:django.request][base.py:284][ERROR][Internal Server Error: /stock_basics/]
Traceback (most recent call last):
  File "/home/kudoxi/.local/lib/python3.5/site-packages/django/core/handlers/base.py", line 149, in get_response
    response = self.process_exception_by_middleware(e, request)
  File "/home/kudoxi/.local/lib/python3.5/site-packages/django/core/handlers/base.py", line 147, in get_response
    response = wrapped_callback(request, *callback_args, **callback_kwargs)
  File "/home/kudoxi/PycharmProjects/StockWeb/index/views.py", line 53, in stock_basics
    lines = json.dumps(eval(date), cls=DateEnconding)
TypeError: eval() arg 1 must be a string, bytes or code object
